Workbook
Name CARENCIA: [1]Planilha1!$E$2:$E$9
Name Carenciaa: [2]Planilha1!$E$2:$E$9
Name Cidade: [3]Dados!$B$4:$B$362
Name valuevx: 42.314159

Sheet Inputs
A1: Quadro Tarifário | I1: Taxa de Disponibilidade (kWh/h) | L1: Estrutura | N1: ∆T
A2: Tarifa | C2: 1.25 | I2: Monofásica | J2: 30 | L2: a | M2: Estrutura Elevada | N2: -3
A3: Tipo de Ligação | C3: Trifásica | F3: Preencher | I3: Bifásica | J3: 50 | L3: b | M3: Laje ou Telhado | N3: 3
A4: Consumo Energético | F4: Escolher | I4: Trifásica | J4: 100 | L4: c | M4: Sobre telhado | N4: 4
A5: Mês | B5: Consumo | C5: Fatura | L5: d | M5: Integrado | N5: 7
A6: Janeiro | B6: 750 | C6: =B6*$C$2 -> 937.5 | I6: Outras Perdas
A7: Fevereiro | B7: 750 | C7: =B7*$C$2 -> 937.5 | I7: K somb | J7: 0
A8: Março | B8: 750 | C8: =B8*$C$2 -> 937.5 | I8: K suj | J8: 0.02
A9: Abril | B9: 750 | C9: =B9*$C$2 -> 937.5 | I9: K tol | J9: 0
A10: Maio | B10: 750 | C10: =B10*$C$2 -> 937.5 | I10: K mis | J10: 0
A11: Junho | B11: 750 | C11: =B11*$C$2 -> 937.5 | I11: K temp | J11: - | K11: Calculada à parte
A12: Julho | B12: 750 | C12: =B12*$C$2 -> 937.5 | I12: K cc | J12: 0.01
A13: Agosto | B13: 750 | C13: =B13*$C$2 -> 937.5 | I13: K spmp | J13: 0.02
A14: Setembro | B14: 750 | C14: =B14*$C$2 -> 937.5 | I14: K inv | J14: 0.04
A15: Outubro | B15: 750 | C15: =B15*$C$2 -> 937.5 | I15: K ca | J15: 0.01
A16: Novembro | B16: 750 | C16: =B16*$C$2 -> 937.5 | I16: Total | J16: =SUM(J7:J15) -> 0.1
A17: Dezembro | B17: 750 | C17: =B17*$C$2 -> 937.5
A18: Média | B18: =AVERAGE(B6:B17) -> 750 | C18: =AVERAGE(C6:C17) -> 937.5
B21: 450
F31: 590
O48: Inclinação
O49: 0
O50: 5
O51: 10
O52: 15
O53: 20
O54: 25
O55: 30
O56: 35
O57: 40
O58: 45
O59: 50
O60: 55
... O67: 90

Sheet Irradiação Solar
A2: 1. | B2: Encontre no Google Maps o local onde será feita a instalação
B3: https://maps.google.com/
A4: 2. | B4: Localize na barra de navegação as coordenadas geográficas do local da instalação
B5: Exemplo ao lado.
A6: 3. | B6: Insira as coordenadas no site do CRESESB para obter os níveis de radiação
B7: http://www.cresesb.cepel.br/index.php?section=sundata | H7: e clique em BUSCAR
B8: Obs.: Não precisa inserir o sinal de negativo
A9: 4. | B9: O site irá mostrar 3 opções para irradiação solar no Plano Horizontal
A10: 5. | B10: Escolha uma opção e cole os dados de irradiação abaixo:
B12: Jan | C12: Fev | D12: Mar | E12: Abr | F12: Mai | G12: Jun | H12: Jul | I12: Ago | J12: Set | K12: Out | L12: Nov | M12: Dez
B13: 6.18 | C13: 6.38 | D13: 5.15 | E13: 4.44 | F13: 3.59 | G13: 3.32 | H13: 3.35 | I13: 4.22 | J13: 4.41 | K13: 5.08 | L13: 5.22 | M13: 6.05
A15: 6. | B15: Insira aqui o valor da latitude: | E15: 22.916321

Sheet Análise Técnica
Y1: =ROUNDUP(U9/C22,0) -> 117
B2: Dimensionamento | H2: Correção HSP e Geração Estimada
B3: Consumo médio Mensal | C3: =Inputs!B18 -> 750 | D3: kWh/mês | I3: Janeiro | J3: Fevereiro | K3: Março | L3: Abril | M3: Maio | N3: Junho | O3: Julho | P3: Agosto | Q3: Setembro | R3: Outubro | S3: Novembro | T3: Dezembro | U3: Média | V3: Total
B4: Tipo de Ligação | C4: =Inputs!C3 -> Trifásica | H4: HSP | I4: ='Irradiação Solar'!B13 -> 6.18 | J4: ='Irradiação Solar'!C13 -> 6.38 | K4: ='Irradiação Solar'!D13 -> 5.15 | L4: ='Irradiação Solar'!E13 -> 4.44 | M4: ='Irradiação Solar'!F13 -> 3.59 | N4: ='Irradiação Solar'!G13 -> 3.32 | O4: ='Irradiação Solar'!H13 -> 3.35 | P4: ='Irradiação Solar'!I13 -> 4.22 | ... T4: ='Irradiação Solar'!M13 -> 6.05 | U4: =AVERAGE(I4:T4) -> 4.7825 | V4: -
B5: Custo de disponibilidade | C5: =VLOOKUP(C4,Inputs!I2:J4,2,FALSE) -> 100 | D5: kWh | H5: K | I5: ='Correção K'!T4 -> 0.99 | J5: ='Correção K'!U4 -> 1.01 | K5: ='Correção K'!V4 -> 1.05 | L5: ='Correção K'!W4 -> 1.08 | M5: ='Correção K'!X4 -> 1.1 | N5: ='Correção K'!Y4 -> 1.1 | O5: ='Correção K'!Z4 -> 1.09 | P5: ='Correção K'!AA4 -> 1.07 | ... T5: ='Correção K'!AE4 -> 0.98 | U5: =AVERAGE(I5:T5) -> 1.0425 | V5: -
B6: Energia de Compensação Mensal | C6: =C3-C5 -> 650 | D6: kWh/mês | H6: HSPk | I6: =I4*I5 -> 6.1182 | J6: =J4*J5 -> 6.4438 | K6: =K4*K5 -> 5.4075 | L6: =L4*L5 -> 4.7952 | M6: =M4*M5 -> 3.949 | N6: =N4*N5 -> 3.652 | O6: =O4*O5 -> 3.6515 | P6: =P4*P5 -> 4.5154 | ... T6: =T4*T5 -> 5.929 | U6: =AVERAGE(I6:T6) -> 4.94555 | V6: -
B7: Energia de Compensação Diária | C7: =C6/30 -> 21.666667 | D7: kWh/m²/dia | H7: Consumo | I7: =Inputs!B6 -> 750 | J7: =Inputs!B7 -> 750 | K7: =Inputs!B8 -> 750 | L7: =Inputs!B9 -> 750 | M7: =Inputs!B10 -> 750 | N7: =Inputs!B11 -> 750 | O7: =Inputs!B12 -> 750 | P7: =Inputs!B13 -> 750 | Q7: =Inputs!B14 -> 750 | R7: =Inputs!B15 -> 750 | S7: =Inputs!B16 -> 750 | T7: =Inputs!B17 -> 750 | U7: =AVERAGE(I7:T7) -> 750 | V7: =SUM(I7:T7) -> 9000
B8: Latitude (Nº inteiro) | C8: =ROUNDUP('Irradiação Solar'!E15,0) -> 23 | D8: ⁰ | H8: Consumo médio | I8: =$U$7 -> 750 | J8: =$U$7 -> 750 | K8: =$U$7 -> 750 | L8: =$U$7 -> 750 | M8: =$U$7 -> 750 | N8: =$U$7 -> 750 | O8: =$U$7 -> 750 | P8: =$U$7 -> 750 | ... T8: =$U$7 -> 750 | U8: =AVERAGE(I8:T8) -> 750 | V8: =SUM(I8:T8) -> 9000
B9: Potencial Solar - Dia | C9: =U6 -> 4.94555 | D9: kWh/m²/dia | H9: Energia Estimada | I9: =I$6*$C$28/1000*30*(1-$C$33) -> 911.2372 | J9: =J$6*$C$28/1000*30*(1-$C$33) -> 959.73166 | K9: =K$6*$C$28/1000*30*(1-$C$33) -> 805.38641 | L9: =L$6*$C$28/1000*30*(1-$C$33) -> 714.1912 | M9: =M$6*$C$28/1000*30*(1-$C$33) -> 588.15921 | N9: =N$6*$C$28/1000*30*(1-$C$33) -> 543.9244 | O9: =O$6*$C$28/1000*30*(1-$C$33) -> 543.84993 | P9: =P$6*$C$28/1000*30*(1-$C$33) -> 672.51813 | ... T9: =T$6*$C$28/1000*30*(1-$C$33) -> 883.05798 | U9: =AVERAGE(I9:T9) -> 736.58415 | V9: =SUM(I9:T9) -> 8839.0098
B10: Potencial Solar - Ano | C10: =C9*365 -> 1805.1257 | H10: Objetivo de Geração | I10: =I8-$C$5 -> 650 | J10: =J8-$C$5 -> 650 | K10: =K8-$C$5 -> 650 | L10: =L8-$C$5 -> 650 | M10: =M8-$C$5 -> 650 | N10: =N8-$C$5 -> 650 | O10: =O8-$C$5 -> 650 | P10: =P8-$C$5 -> 650 | ... T10: =T8-$C$5 -> 650 | U10: =AVERAGE(I10:T10) -> 650
B11: Inclinação ideal de projeto | C11: =3.7+(0.69*C8) -> 19.57 | D11: ⁰
B12: Inclinação Real (Escolha inclinação + Próxima) | C12: 10 | D12: ⁰
B13: Potencia Teórica | C13: =C7/C9 -> 4.3810429 | D13: Kwp teórico | G13: Preencher
B14: Perdas Totais | C14: =C33 -> 0.21196417 | G14: Escolher
B15: Geração desejada | C15: 1
B16: Sistema Real para Geração Máxima (100%) | C16: =(1+C14)*C13*C15 -> 5.309667 | D16: Kwp
B18: Característiccas Técnicas
B19: Potência nominal dos Módulos | C19: 700 | D19: W
B20: Número necessários de Módulos | C20: =ROUNDUP(C15*(C16*1000/C19),0)+C21 -> 9 | D20: un.
B21: Ajuste manual do número de módulos | C21: 1 | D21: un.
B22: Potência do Sistema | C22: =C20*C19/1000 -> 6.3 | D22: kWp
B23: Potência Nominal do Inversor que se pretende usar | C23: 6 | D23: kW
B24: Nº de Inversores | C24: 1 | D24: un. | E24: =IF(D25="OK","","O ideal é que o fator de dimensionamento Global fique entre 0,75 e 1,25")
B25: Fotor de Dimensionamento Global (Pcc/Pca) | C25: =C22/(C23*C24) -> 1.05 | D25: =IF(C25<0.75,"Atenção",IF(C25>1.3,"Atenção","OK")) -> OK
F26: 8
B27: Caracterização das Perdas
B28: Potência Instalada (Wp) | C28: =C22*1000 -> 6300 | D28: Wp
B29: Coef. Temp para Pmax | C29: -0.0041 | D29: %/°C
B30: Outras Perdas (Ver aba Inputs) | C30: =Inputs!J16 -> 0.1 | D30: %
B31: Perda média por temperatura | C31: =E69 -> 0.11196417 | D31: %
B32: Perda Transformador 380V/220V | C32: 0 | D32: %
B33: Fator de Perdas | C33: =C30+C31+C32 -> 0.21196417 | D33: %
B34: Selecione Tipo de Estrutura (Na ordem, a,b,c,d) | C34: Sobre telhado | D34: -
B35: Diferença à Tref | C35: =VLOOKUP($C34,Inputs!M2:N5,2,FALSE) -> 4 | D35: ºC
B36: ∆T | C36: =25+C35 -> 29 | D36: C
B55: Perdas por Temperatura (Selecione abaixo a cidade mais próxima, ver aba "Temp. Média"
B56: Rio de Janeiro | C56: Temp. Média | D56: Temp. calc | E56: K temp
B57: Janeiro | C57: =VLOOKUP($B56,'Temp. Média'!$A:$N,6,FALSE) -> 24.4 | D57: =C57+($C$36-25) -> 28.4 | E57: =-$C$29*D57 -> 0.11644
B58: Fevereiro | C58: =VLOOKUP($B56,'Temp. Média'!$A:$N,6,FALSE) -> 24.4 | D58: =C58+($C$36-25) -> 28.4 | E58: =-$C$29*D58 -> 0.11644
B59: Março | C59: =VLOOKUP($B56,'Temp. Média'!$A:$N,6,FALSE) -> 24.4 | D59: =C59+($C$36-25) -> 28.4 | E59: =-$C$29*D59 -> 0.11644
...

Sheet Análise Financeira
B2: Custo Global do Projeto | E2: Demonstrativo Energético e Financeiro do primeiro ano com Energia Solar: | AO2: Mês | AP2: Poupança e Conta de Energia | AQ2: Energia Solar
B3: Potência Nominal do Sistema | C3: ='Análise Técnica'!C22 -> 6.3 | E3: Mês | F3: Consumo | G3: Geração | H3: Débito | I3: Crédito | J3: Disponibilidade | K3: Além da Disp. | L3: Créditos | M3: Faturaveis | N3: Sem Energia Solar | O3: Com Energia Solar | P3: Economia (R$) | Q3: Economia (%) | R3: Retorno Investimento | T3: Ano | U3: Mês | W3: Consumo | X3: Geração | Y3: Débito | Z3: Crédito mês | AA3: TD | AB3: Além TD | AC3: Créditos | AD3: Faturáveis | AE3: Sem Energia Solar | AF3: Com Energia Solar | AG3: Economia | AH3: Custos/Manutenção | AI3: Subtotal | AJ3: Fluxo Final | AK3: Economia | AL3: Gasto Acumulado | AM3: Retorno Inv. | AO3: 0 | AP3: =C4 -> 14234.494 | AQ3: =-AP3 -> -14234.494
B4: PREÇO TOTAL | C4: =Custos!D24 -> 14234.494 | E4: Janeiro | F4: =Inputs!B6 -> 750 | G4: ='Análise Técnica'!I9 -> 911.2372 | H4: =IF(G4-F4<0,F4-G4,0) -> 0 | I4: =IF(G4-F4>0,G4-F4,0) -> 161.2372 | J4: =$C$7 -> 100 | K4: =IF(H4-$C$7>0,H4-$C$7,0) -> 0 | L4: =I4 -> 161.2372 | M4: =K4 -> 0 | N4: =Inputs!C6 -> 937.5 | O4: =IF(I4>0, (J4*$C$8),(J4+M4)*$C$8) -> 125 | P4: =N4-O4 -> 812.5 | Q4: =1-(O4/N4) -> 0.86666667 | R4: =P4/$C$4 -> 0.057079654 | T4: 0 | U4: 1 | V4: Janeiro | W4: ='Análise Técnica'!$C$3 -> 750 | X4: =G4 -> 911.2372 | Y4: =IF(X4-W4<0,W4-X4,0) -> 0 | Z4: =IF(X4-W4>0,X4-W4,0) -> 161.2372 | AA4: =$C$7 -> 100 | AB4: =IF(Y4-$C$7>0,Y4-$C$7,0) -> 0 | AC4: =Z4 -> 161.2372 | AD4: =AB4 -> 0 | AE4: =($C$10*(1+$C$30)^T4) -> 937.5 | AF4: =IF(Z4>0,((AA4*$C$8)*((1+$C$30)^T4)),((AA4+AD4)*$C$8)*(1+$C$30)^T4) -> 125 | AG4: =AE4-AF4 -> 812.5 | AH4: =$C$4 -> 14234.494 | AI4: =AG4-AH4 -> -13421.994 | AK4: =1-(AF4/AE4) -> 0.86666667 | AL4: =AE4 -> 937.5 | AM4: =AG4/$C$4 -> 0.057079654 | AO4: 1 | AP4: =($C$4*(1+($C$36-$C$39))^AO4)-AE4 -> 13337.325 | AQ4: =AI4 -> -13421.994
B5: Conumo médio mensal | C5: =Inputs!B18 -> 750 | E5: Fevereiro | F5: =Inputs!B7 -> 750 | G5: ='Análise Técnica'!J9 -> 959.73166 | H5: =IF(G5-F5<0,F5-G5,0) -> 0 | I5: =IF(G5-F5>0,G5-F5,0) -> 209.73166 | J5: =$C$7 -> 100 | K5: =IF(H5-$C$7>0,H5-$C$7,0) -> 0 | L5: =IF(L4-(H5-$C$7)>0,IF(H5>0,IF(H5<$C$7,L4,L4-(H5-$C$7)),I5+L4),0) -> 370.96886 | M5: =K5 -> 0 | N5: =Inputs!C7 -> 937.5 | O5: =IF(I5>0, (J5*$C$8),(J5+M5)*$C$8) -> 125 | P5: =N5-O5 -> 812.5 | Q5: =1-(O5/N5) -> 0.86666667 | R5: =P5/$C$4 -> 0.057079654 | T5: 0 | U5: 2 | V5: Fevereiro | W5: ='Análise Técnica'!$C$3 -> 750 | X5: =G5 -> 959.73166 | Y5: =IF(X5-W5<0,W5-X5,0) -> 0 | Z5: =IF(X5-W5>0,X5-W5,0) -> 209.73166 | AA5: =$C$7 -> 100 | AB5: =IF(Y5-$C$7>0,Y5-$C$7,0) -> 0 | AC5: =IF(AC4-(Y5-$C$7)>0,IF(Y5>0,IF(Y5<$C$7,AC4,AC4-(Y5-$C$7)),Z5+AC4),0) -> 370.96886 | AD5: =IF(AB5-AC4<0,0,AB5-AC4) -> 0 | AE5: =($C$10*(1+$C$30)^T5) -> 937.5 | AF5: =IF(Z5>0,((AA5*$C$8)*((1+$C$30)^T5)),((AA5+AD5)*$C$8)*(1+$C$30)^T5) -> 125 | AG5: =AE5-AF5 -> 812.5 | AH5: =$C$28/12*($C$4*((1+$C$29)^T5))+IF($C$31=T5,$C$33/12,0) -> 0 | AI5: =AG5-AH5 -> 812.5 | AJ5: =AI4+AI5 -> -12609.494 | AK5: =1-(AF5/AE5) -> 0.86666667 | AL5: =AL4+AE5 -> 1875 | AM5: =AG5/$C$4 -> 0.057079654 | AO5: 2 | AP5: =($C$4*(1+($C$36-$C$39))^AO5)-AE5 -> 13377.771 | AQ5: =AJ5 -> -12609.494
B6: Percentual Médio de Geração em 25 anos | C6: =G47/F47 -> 0.90126451 | E6: Março | F6: =Inputs!B8 -> 750 | G6: ='Análise Técnica'!K9 -> 805.38641 | H6: =IF(G6-F6<0,F6-G6,0) -> 0 | I6: =IF(G6-F6>0,G6-F6,0) -> 55.386412 | J6: =$C$7 -> 100 | K6: =IF(H6-$C$7>0,H6-$C$7,0) -> 0 | L6: =IF(L5-(H6-$C$7)>0,IF(H6>0,IF(H6<$C$7,L5,L5-(H6-$C$7)),I6+L5),0) -> 426.35527 | M6: =K6 -> 0 | N6: =Inputs!C8 -> 937.5 | O6: =IF(I6>0, (J6*$C$8),(J6+M6)*$C$8) -> 125 | P6: =N6-O6 -> 812.5 | Q6: =1-(O6/N6) -> 0.86666667 | R6: =P6/$C$4 -> 0.057079654 | T6: 0 | U6: 3 | V6: Março | W6: ='Análise Técnica'!$C$3 -> 750 | X6: =G6 -> 805.38641 | Y6: =IF(X6-W6<0,W6-X6,0) -> 0 | Z6: =IF(X6-W6>0,X6-W6,0) -> 55.386412 | AA6: =$C$7 -> 100 | AB6: =IF(Y6-$C$7>0,Y6-$C$7,0) -> 0 | AC6: =IF(AC5-(Y6-$C$7)>0,IF(Y6>0,IF(Y6<$C$7,AC5,AC5-(Y6-$C$7)),Z6+AC5),0) -> 426.35527 | AD6: =IF(AB6-AC5<0,0,AB6-AC5) -> 0 | AE6: =($C$10*(1+$C$30)^T6) -> 937.5 | AF6: =IF(Z6>0,((AA6*$C$8)*((1+$C$30)^T6)),((AA6+AD6)*$C$8)*(1+$C$30)^T6) -> 125 | AG6: =AE6-AF6 -> 812.5 | AH6: =$C$28/12*($C$4*((1+$C$29)^T6))+IF($C$31=T6,$C$33/12,0) -> 0 | AI6: =AG6-AH6 -> 812.5 | AJ6: =AJ5+AI6 -> -11796.994 | AK6: =1-(AF6/AE6) -> 0.86666667 | AL6: =AL5+AE6 -> 2812.5 | AM6: =AG6/$C$4 -> 0.057079654 | AO6: 3 | AP6: =($C$4*(1+($C$36-$C$39))^AO6)-AE6 -> 13418.331 | AQ6: =AJ6 -> -11796.994
B7: Custo de Disponibilidade | C7: ='Análise Técnica'!C5 -> 100 | E7: Abril | F7: =Inputs!B9 -> 750 | G7: ='Análise Técnica'!L9 -> 714.1912 | H7: =IF(G7-F7<0,F7-G7,0) -> 35.808798 | I7: =IF(G7-F7>0,G7-F7,0) -> 0 | J7: =$C$7 -> 100 | K7: =IF(H7-$C$7>0,H7-$C$7,0) -> 0 | L7: =IF(L6-(H7-$C$7)>0,IF(H7>0,IF(H7<$C$7,L6,L6-(H7-$C$7)),I7+L6),0) -> 426.35527 | M7: =K7 -> 0 | N7: =Inputs!C9 -> 937.5 | O7: =IF(I7>0, (J7*$C$8),(J7+M7)*$C$8) -> 125 | P7: =N7-O7 -> 812.5 | Q7: =1-(O7/N7) -> 0.86666667 | R7: =P7/$C$4 -> 0.057079654 | T7: 0 | U7: 4 | V7: Abril | W7: ='Análise Técnica'!$C$3 -> 750 | X7: =G7 -> 714.1912 | Y7: =IF(X7-W7<0,W7-X7,0) -> 35.808798 | Z7: =IF(X7-W7>0,X7-W7,0) -> 0 | AA7: =$C$7 -> 100 | AB7: =IF(Y7-$C$7>0,Y7-$C$7,0) -> 0 | AC7: =IF(AC6-(Y7-$C$7)>0,IF(Y7>0,IF(Y7<$C$7,AC6,AC6-(Y7-$C$7)),Z7+AC6),0) -> 426.35527 | AD7: =IF(AB7-AC6<0,0,AB7-AC6) -> 0 | AE7: =($C$10*(1+$C$30)^T7) -> 937.5 | AF7: =IF(Z7>0,((AA7*$C$8)*((1+$C$30)^T7)),((AA7+AD7)*$C$8)*(1+$C$30)^T7) -> 125 | AG7: =AE7-AF7 -> 812.5 | AH7: =$C$28/12*($C$4*((1+$C$29)^T7))+IF($C$31=T7,$C$33/12,0) -> 0 | AI7: =AG7-AH7 -> 812.5 | AJ7: =AJ6+AI7 -> -10984.494 | AK7: =1-(AF7/AE7) -> 0.86666667 | AL7: =AL6+AE7 -> 3750 | AM7: =AG7/$C$4 -> 0.057079654 | AO7: 4 | AP7: =($C$4*(1+($C$36-$C$39))^AO7)-AE7 -> 13459.005 | AQ7: =AJ7 -> -10984.494
B8: Tarifa Energética | C8: =Inputs!C2 -> 1.25 | E8: Maio | F8: =Inputs!B10 -> 750 | G8: ='Análise Técnica'!M9 -> 588.15921 | H8: =IF(G8-F8<0,F8-G8,0) -> 161.84079 | I8: =IF(G8-F8>0,G8-F8,0) -> 0 | J8: =$C$7 -> 100 | K8: =IF(H8-$C$7>0,H8-$C$7,0) -> 61.840787 | L8: =IF(L7-(H8-$C$7)>0,IF(H8>0,IF(H8<$C$7,L7,L7-(H8-$C$7)),I8+L7),0) -> 364.51449 | M8: =K8 -> 61.840787 | N8: =Inputs!C10 -> 937.5 | O8: =IF(I8>0, (J8*$C$8),(J8+M8)*$C$8) -> 202.30098 | P8: =N8-O8 -> 735.19902 | Q8: =1-(O8/N8) -> 0.78421228 | R8: =P8/$C$4 -> 0.051649114 | T8: 0 | U8: 5 | V8: Maio | W8: ='Análise Técnica'!$C$3 -> 750 | X8: =G8 -> 588.15921 | Y8: =IF(X8-W8<0,W8-X8,0) -> 161.84079 | Z8: =IF(X8-W8>0,X8-W8,0) -> 0 | AA8: =$C$7 -> 100 | AB8: =IF(Y8-$C$7>0,Y8-$C$7,0) -> 61.840787 | AC8: =IF(AC7-(Y8-$C$7)>0,IF(Y8>0,IF(Y8<$C$7,AC7,AC7-(Y8-$C$7)),Z8+AC7),0) -> 364.51449 | AD8: =IF(AB8-AC7<0,0,AB8-AC7) -> 0 | AE8: =($C$10*(1+$C$30)^T8) -> 937.5 | AF8: =IF(Z8>0,((AA8*$C$8)*((1+$C$30)^T8)),((AA8+AD8)*$C$8)*(1+$C$30)^T8) -> 125 | AG8: =AE8-AF8 -> 812.5 | AH8: =$C$28/12*($C$4*((1+$C$29)^T8))+IF($C$31=T8,$C$33/12,0) -> 0 | AI8: =AG8-AH8 -> 812.5 | AJ8: =AJ7+AI8 -> -10171.994 | AK8: =1-(AF8/AE8) -> 0.86666667 | AL8: =AL7+AE8 -> 4687.5 | AM8: =AG8/$C$4 -> 0.057079654 | AO8: 5 | AP8: =($C$4*(1+($C$36-$C$39))^AO8)-AE8 -> 13499.796 | AQ8: =AJ8 -> -10171.994
B9: Tipo de Ligação | C9: =Inputs!C3 -> Trifásica | E9: Junho | F9: =Inputs!B11 -> 750 | G9: ='Análise Técnica'!N9 -> 543.9244 | H9: =IF(G9-F9<0,F9-G9,0) -> 206.0756 | I9: =IF(G9-F9>0,G9-F9,0) -> 0 | J9: =$C$7 -> 100 | K9: =IF(H9-$C$7>0,H9-$C$7,0) -> 106.0756 | L9: =IF(L8-(H9-$C$7)>0,IF(H9>0,IF(H9<$C$7,L8,L8-(H9-$C$7)),I9+L8),0) -> 258.43888 | M9: =K9 -> 106.0756 | N9: =Inputs!C11 -> 937.5 | O9: =IF(I9>0, (J9*$C$8),(J9+M9)*$C$8) -> 257.5945 | P9: =N9-O9 -> 679.9055 | Q9: =1-(O9/N9) -> 0.72523253 | R9: =P9/$C$4 -> 0.04776464 | T9: 0 | U9: 6 | V9: Junho | W9: ='Análise Técnica'!$C$3 -> 750 | X9: =G9 -> 543.9244 | Y9: =IF(X9-W9<0,W9-X9,0) -> 206.0756 | Z9: =IF(X9-W9>0,X9-W9,0) -> 0 | AA9: =$C$7 -> 100 | AB9: =IF(Y9-$C$7>0,Y9-$C$7,0) -> 106.0756 | AC9: =IF(AC8-(Y9-$C$7)>0,IF(Y9>0,IF(Y9<$C$7,AC8,AC8-(Y9-$C$7)),Z9+AC8),0) -> 258.43888 | AD9: =IF(AB9-AC8<0,0,AB9-AC8) -> 0 | AE9: =($C$10*(1+$C$30)^T9) -> 937.5 | AF9: =IF(Z9>0,((AA9*$C$8)*((1+$C$30)^T9)),((AA9+AD9)*$C$8)*(1+$C$30)^T9) -> 125 | AG9: =AE9-AF9 -> 812.5 | AH9: =$C$28/12*($C$4*((1+$C$29)^T9))+IF($C$31=T9,$C$33/12,0) -> 0 | AI9: =AG9-AH9 -> 812.5 | AJ9: =AJ8+AI9 -> -9359.4942 | AK9: =1-(AF9/AE9) -> 0.86666667 | AL9: =AL8+AE9 -> 5625 | AM9: =AG9/$C$4 -> 0.057079654 | AO9: 6 | AP9: =($C$4*(1+($C$36-$C$39))^AO9)-AE9 -> 13540.701 | AQ9: =AJ9 -> -9359.4942
B10: Fatura média atual | C10: =Inputs!C18 -> 937.5 | E10: Julho | F10: =Inputs!B12 -> 750 | G10: ='Análise Técnica'!O9 -> 543.84993 | H10: =IF(G10-F10<0,F10-G10,0) -> 206.15007 | I10: =IF(G10-F10>0,G10-F10,0) -> 0 | J10: =$C$7 -> 100 | K10: =IF(H10-$C$7>0,H10-$C$7,0) -> 106.15007 | L10: =IF(L9-(H10-$C$7)>0,IF(H10>0,IF(H10<$C$7,L9,L9-(H10-$C$7)),I10+L9),0) -> 152.28881 | M10: =K10 -> 106.15007 | N10: =Inputs!C12 -> 937.5 | O10: =IF(I10>0, (J10*$C$8),(J10+M10)*$C$8) -> 257.68759 | P10: =N10-O10 -> 679.81241 | Q10: =1-(O10/N10) -> 0.72513324 | R10: =P10/$C$4 -> 0.047758101 | T10: 0 | U10: 7 | V10: Julho | W10: ='Análise Técnica'!$C$3 -> 750 | X10: =G10 -> 543.84993 | Y10: =IF(X10-W10<0,W10-X10,0) -> 206.15007 | Z10: =IF(X10-W10>0,X10-W10,0) -> 0 | AA10: =$C$7 -> 100 | AB10: =IF(Y10-$C$7>0,Y10-$C$7,0) -> 106.15007 | AC10: =IF(AC9-(Y10-$C$7)>0,IF(Y10>0,IF(Y10<$C$7,AC9,AC9-(Y10-$C$7)),Z10+AC9),0) -> 152.28881 | AD10: =IF(AB10-AC9<0,0,AB10-AC9) -> 0 | AE10: =($C$10*(1+$C$30)^T10) -> 937.5 | AF10: =IF(Z10>0,((AA10*$C$8)*((1+$C$30)^T10)),((AA10+AD10)*$C$8)*(1+$C$30)^T10) -> 125 | AG10: =AE10-AF10 -> 812.5 | AH10: =$C$28/12*($C$4*((1+$C$29)^T10))+IF($C$31=T10,$C$33/12,0) -> 0 | AI10: =AG10-AH10 -> 812.5 | AJ10: =AJ9+AI10 -> -8546.9942 | AK10: =1-(AF10/AE10) -> 0.86666667 | AL10: =AL9+AE10 -> 6562.5 | AM10: =AG10/$C$4 -> 0.057079654 | AO10: 7 | AP10: =($C$4*(1+($C$36-$C$39))^AO10)-AE10 -> 13581.723 | AQ10: =AJ10 -> -8546.9942
B11: Outputs e Resultados | E11: Agosto | F11: =Inputs!B13 -> 750 | G11: ='Análise Técnica'!P9 -> 672.51813 | H11: =IF(G11-F11<0,F11-G11,0) -> 77.481867 | I11: =IF(G11-F11>0,G11-F11,0) -> 0 | J11: =$C$7 -> 100 | K11: =IF(H11-$C$7>0,H11-$C$7,0) -> 0 | L11: =IF(L10-(H11-$C$7)>0,IF(H11>0,IF(H11<$C$7,L10,L10-(H11-$C$7)),I11+L10),0) -> 152.28881 | M11: =K11 -> 0 | N11: =Inputs!C13 -> 937.5 | O11: =IF(I11>0, (J11*$C$8),(J11+M11)*$C$8) -> 125 | P11: =N11-O11 -> 812.5 | Q11: =1-(O11/N11) -> 0.86666667 | R11: =P11/$C$4 -> 0.057079654 | T11: 0 | U11: 8 | V11: Agosto | W11: ='Análise Técnica'!$C$3 -> 750 | X11: =G11 -> 672.51813 | Y11: =IF(X11-W11<0,W11-X11,0) -> 77.481867 | Z11: =IF(X11-W11>0,X11-W11,0) -> 0 | AA11: =$C$7 -> 100 | AB11: =IF(Y11-$C$7>0,Y11-$C$7,0) -> 0 | AC11: =IF(AC10-(Y11-$C$7)>0,IF(Y11>0,IF(Y11<$C$7,AC10,AC10-(Y11-$C$7)),Z11+AC10),0) -> 152.28881 | AD11: =IF(AB11-AC10<0,0,AB11-AC10) -> 0 | AE11: =($C$10*(1+$C$30)^T11) -> 937.5 | AF11: =IF(Z11>0,((AA11*$C$8)*((1+$C$30)^T11)),((AA11+AD11)*$C$8)*(1+$C$30)^T11) -> 125 | AG11: =AE11-AF11 -> 812.5 | AH11: =$C$28/12*($C$4*((1+$C$29)^T11))+IF($C$31=T11,$C$33/12,0) -> 0 | AI11: =AG11-AH11 -> 812.5 | AJ11: =AJ10+AI11 -> -7734.4942 | AK11: =1-(AF11/AE11) -> 0.86666667 | AL11: =AL10+AE11 -> 7500 | AM11: =AG11/$C$4 -> 0.057079654 | AO11: 8 | AP11: =($C$4*(1+($C$36-$C$39))^AO11)-AE11 -> 13622.861 | AQ11: =AJ11 -> -7734.4942
B12: Payback Ano | C12: =VLOOKUP("Payback",S4:T303,2,0) -> 1 | E12: Setembro | F12: =Inputs!B14 -> 750 | G12: ='Análise Técnica'!Q9 -> 683.09279 | H12: =IF(G12-F12<0,F12-G12,0) -> 66.907214 | I12: =IF(G12-F12>0,G12-F12,0) -> 0 | J12: =$C$7 -> 100 | K12: =IF(H12-$C$7>0,H12-$C$7,0) -> 0 | L12: =IF(L11-(H12-$C$7)>0,IF(H12>0,IF(H12<$C$7,L11,L11-(H12-$C$7)),I12+L11),0) -> 152.28881 | M12: =K12 -> 0 | N12: =Inputs!C14 -> 937.5 | O12: =IF(I12>0, (J12*$C$8),(J12+M12)*$C$8) -> 125 | P12: =N12-O12 -> 812.5 | Q12: =1-(O12/N12) -> 0.86666667 | R12: =P12/$C$4 -> 0.057079654 | T12: 0 | U12: 9 | V12: Setembro | W12: ='Análise Técnica'!$C$3 -> 750 | X12: =G12 -> 683.09279 | Y12: =IF(X12-W12<0,W12-X12,0) -> 66.907214 | Z12: =IF(X12-W12>0,X12-W12,0) -> 0 | AA12: =$C$7 -> 100 | AB12: =IF(Y12-$C$7>0,Y12-$C$7,0) -> 0 | AC12: =IF(AC11-(Y12-$C$7)>0,IF(Y12>0,IF(Y12<$C$7,AC11,AC11-(Y12-$C$7)),Z12+AC11),0) -> 152.28881 | AD12: =IF(AB12-AC11<0,0,AB12-AC11) -> 0 | AE12: =($C$10*(1+$C$30)^T12) -> 937.5 | AF12: =IF(Z12>0,((AA12*$C$8)*((1+$C$30)^T12)),((AA12+AD12)*$C$8)*(1+$C$30)^T12) -> 125 | AG12: =AE12-AF12 -> 812.5 | AH12: =$C$28/12*($C$4*((1+$C$29)^T12))+IF($C$31=T12,$C$33/12,0) -> 0 | AI12: =AG12-AH12 -> 812.5 | AJ12: =AJ11+AI12 -> -6921.9942 | AK12: =1-(AF12/AE12) -> 0.86666667 | AL12: =AL11+AE12 -> 8437.5 | AM12: =AG12/$C$4 -> 0.057079654 | AO12: 9 | AP12: =($C$4*(1+($C$36-$C$39))^AO12)-AE12 -> 13664.115 | AQ12: =AJ12 -> -6921.9942
B13: Payback Mês | C13: =VLOOKUP("Payback",S4:V303,3,0) -> 6 | E13: Outubro | F13: =Inputs!B15 -> 750 | G13: ='Análise Técnica'!R9 -> 764.17505 | H13: =IF(G13-F13<0,F13-G13,0) -> 0 | I13: =IF(G13-F13>0,G13-F13,0) -> 14.175054 | J13: =$C$7 -> 100 | K13: =IF(H13-$C$7>0,H13-$C$7,0) -> 0 | L13: =IF(L12-(H13-$C$7)>0,IF(H13>0,IF(H13<$C$7,L12,L12-(H13-$C$7)),I13+L12),0) -> 166.46386 | M13: =K13 -> 0 | N13: =Inputs!C15 -> 937.5 | O13: =IF(I13>0, (J13*$C$8),(J13+M13)*$C$8) -> 125 | P13: =N13-O13 -> 812.5 | Q13: =1-(O13/N13) -> 0.86666667 | R13: =P13/$C$4 -> 0.057079654 | T13: 0 | U13: 10 | V13: Outubro | W13: ='Análise Técnica'!$C$3 -> 750 | X13: =G13 -> 764.17505 | Y13: =IF(X13-W13<0,W13-X13,0) -> 0 | Z13: =IF(X13-W13>0,X13-W13,0) -> 14.175054 | AA13: =$C$7 -> 100 | AB13: =IF(Y13-$C$7>0,Y13-$C$7,0) -> 0 | AC13: =IF(AC12-(Y13-$C$7)>0,IF(Y13>0,IF(Y13<$C$7,AC12,AC12-(Y13-$C$7)),Z13+AC12),0) -> 166.46386 | AD13: =IF(AB13-AC12<0,0,AB13-AC12) -> 0 | AE13: =($C$10*(1+$C$30)^T13) -> 937.5 | AF13: =IF(Z13>0,((AA13*$C$8)*((1+$C$30)^T13)),((AA13+AD13)*$C$8)*(1+$C$30)^T13) -> 125 | AG13: =AE13-AF13 -> 812.5 | AH13: =$C$28/12*($C$4*((1+$C$29)^T13))+IF($C$31=T13,$C$33/12,0) -> 0 | AI13: =AG13-AH13 -> 812.5 | AJ13: =AJ12+AI13 -> -6109.4942 | AK13: =1-(AF13/AE13) -> 0.86666667 | AL13: =AL12+AE13 -> 9375 | AM13: =AG13/$C$4 -> 0.057079654 | AO13: 10 | AP13: =($C$4*(1+($C$36-$C$39))^AO13)-AE13 -> 13705.486 | AQ13: =AJ13 -> -6109.4942
B14: Retorno no Primeiro Ano | C14: =J22/C4 -> 0.68495584 | E14: Novembro | F14: =Inputs!B16 -> 750 | G14: ='Análise Técnica'!S9 -> 769.68579 | H14: =IF(G14-F14<0,F14-G14,0) -> 0 | I14: =IF(G14-F14>0,G14-F14,0) -> 19.685789 | J14: =$C$7 -> 100 | K14: =IF(H14-$C$7>0,H14-$C$7,0) -> 0 | L14: =IF(L13-(H14-$C$7)>0,IF(H14>0,IF(H14<$C$7,L13,L13-(H14-$C$7)),I14+L13),0) -> 186.14965 | M14: =K14 -> 0 | N14: =Inputs!C16 -> 937.5 | O14: =IF(I14>0, (J14*$C$8),(J14+M14)*$C$8) -> 125 | P14: =N14-O14 -> 812.5 | Q14: =1-(O14/N14) -> 0.86666667 | R14: =P14/$C$4 -> 0.057079654 | T14: 0 | U14: 11 | V14: Novembro | W14: ='Análise Técnica'!$C$3 -> 750 | X14: =G14 -> 769.68579 | Y14: =IF(X14-W14<0,W14-X14,0) -> 0 | Z14: =IF(X14-W14>0,X14-W14,0) -> 19.685789 | AA14: =$C$7 -> 100 | AB14: =IF(Y14-$C$7>0,Y14-$C$7,0) -> 0 | AC14: =IF(AC13-(Y14-$C$7)>0,IF(Y14>0,IF(Y14<$C$7,AC13,AC13-(Y14-$C$7)),Z14+AC13),0) -> 186.14965 | AD14: =IF(AB14-AC13<0,0,AB14-AC13) -> 0 | AE14: =($C$10*(1+$C$30)^T14) -> 937.5 | AF14: =IF(Z14>0,((AA14*$C$8)*((1+$C$30)^T14)),((AA14+AD14)*$C$8)*(1+$C$30)^T14) -> 125 | AG14: =AE14-AF14 -> 812.5 | AH14: =$C$28/12*($C$4*((1+$C$29)^T14))+IF($C$31=T14,$C$33/12,0) -> 0 | AI14: =AG14-AH14 -> 812.5 | AJ14: =AJ13+AI14 -> -5296.9942 | AK14: =1-(AF14/AE14) -> 0.86666667 | AL14: =AL13+AE14 -> 10312.5 | AM14: =AG14/$C$4 -> 0.057079654 | AO14: 11 | AP14: =($C$4*(1+($C$36-$C$39))^AO14)-AE14 -> 13746.975 | AQ14: =AJ14 -> -5296.9942
B15: Retorno no Primeiro Ano $ | C15: =J22 -> 9750 | E15: Dezembro | F15: =Inputs!B17 -> 750 | G15: ='Análise Técnica'!T9 -> 883.05798 | H15: =IF(G15-F15<0,F15-G15,0) -> 0 | I15: =IF(G15-F15>0,G15-F15,0) -> 133.05798 | J15: =$C$7 -> 100 | K15: =IF(H15-$C$7>0,H15-$C$7,0) -> 0 | L15: =IF(L14-(H15-$C$7)>0,IF(H15>0,IF(H15<$C$7,L14,L14-(H15-$C$7)),I15+L14),0) -> 319.20763 | M15: =K15 -> 0 | N15: =Inputs!C17 -> 937.5 | O15: =IF(I15>0, (J15*$C$8),(J15+M15)*$C$8) -> 125 | P15: =N15-O15 -> 812.5 | Q15: =1-(O15/N15) -> 0.86666667 | R15: =P15/$C$4 -> 0.057079654 | T15: 0 | U15: 12 | V15: Dezembro | W15: ='Análise Técnica'!$C$3 -> 750 | X15: =G15 -> 883.05798 | Y15: =IF(X15-W15<0,W15-X15,0) -> 0 | Z15: =IF(X15-W15>0,X15-W15,0) -> 133.05798 | AA15: =$C$7 -> 100 | AB15: =IF(Y15-$C$7>0,Y15-$C$7,0) -> 0 | AC15: =IF(AC14-(Y15-$C$7)>0,IF(Y15>0,IF(Y15<$C$7,AC14,AC14-(Y15-$C$7)),Z15+AC14),0) -> 319.20763 | AD15: =IF(AB15-AC14<0,0,AB15-AC14) -> 0 | AE15: =($C$10*(1+$C$30)^T15) -> 937.5 | AF15: =IF(Z15>0,((AA15*$C$8)*((1+$C$30)^T15)),((AA15+AD15)*$C$8)*(1+$C$30)^T15) -> 125 | AG15: =AE15-AF15 -> 812.5 | AH15: =$C$28/12*($C$4*((1+$C$29)^T15))+IF($C$31=T15,$C$33/12,0) -> 0 | AI15: =AG15-AH15 -> 812.5 | AJ15: =AJ14+AI15 -> -4484.4942 | AK15: =1-(AF15/AE15) -> 0.86666667 | AL15: =AL14+AE15 -> 11250 | AM15: =AG15/$C$4 -> 0.057079654 | AO15: 12 | AP15: =($C$4*(1+($C$36-$C$39))^AO15)-AE15 -> 13788.581 | AQ15: =AJ15 -> -4484.4942
B16: Reais por Watt Instalado | C16: =C4/C3/1000 -> 2.2594435 | E16: Média | F16: =AVERAGE(F4:F15) -> 750 | G16: =AVERAGE(G4:G15) -> 736.58415 | H16: =AVERAGE(H4:H15) -> 62.855362 | I16: =AVERAGE(I4:I15) -> 49.439508 | J16: =AVERAGE(J4:J15) -> 100 | K16: =AVERAGE(K4:K15) -> 22.838872 | L16: =AVERAGE(L4:L15) -> 261.3798 | M16: =AVERAGE(M4:M15) -> 22.838872 | N16: =AVERAGE(N4:N15) -> 937.5 | O16: =O17/12 -> 153.54859 | P16: =P17/12 -> 783.95141 | Q16: =AVERAGE(Q4:Q15) -> 0.83621484 | R16: =AVERAGE(R4:R15) -> 0.055074061 | S16: =IF(AND(AJ16>0,AJ15<0),"Payback","") | T16: 1 | U16: 1 | V16: Janeiro | W16: ='Análise Técnica'!$C$3 -> 750 | X16: =X4*(1-$C$26) -> 902.12483 | Y16: =IF(X16-W16<0,W16-X16,0) -> 0 | Z16: =IF(X16-W16>0,X16-W16,0) -> 152.12483 | AA16: =$C$7 -> 100 | AB16: =IF(Y16-$C$7>0,Y16-$C$7,0) -> 0 | AC16: =IF(AC15-(Y16-$C$7)>0,IF(Y16>0,IF(Y16<$C$7,AC15,AC15-(Y16-$C$7)),Z16+AC15),0) -> 471.33246 | AD16: =IF(AB16-AC15<0,0,AB16-AC15) -> 0 | AE16: =($C$10*(1+$C$30)^T16) -> 1012.5 | AF16: =IF(Z16>0,((AA16*$C$8)*((1+$C$30)^T16)),((AA16+AD16)*$C$8)*(1+$C$30)^T16) -> 135 | AG16: =AE16-AF16 -> 877.5 | AH16: =$C$28/12*($C$4*((1+$C$29)^T16))+IF($C$31=T16,$C$33/12,0) -> 0 | AI16: =AG16-AH16 -> 877.5 | AJ16: =AJ15+AI16 -> -3606.9942 | AK16: =1-(AF16/AE16) -> 0.86666667 | AL16: =AL15+AE16 -> 12262.5 | AM16: =AG16/$C$4 -> 0.061646026 | AO16: 13 | AP16: =($C$4*(1+($C$36-$C$39))^AO16)-AE16 -> 13755.305 | AQ16: =AJ16 -> -3606.9942
B17: VPL | C17: =NPV($C$34,M22:M46) -> 162106.77 | E17: Total | F17: =SUM(F4:F15) -> 9000 | G17: =SUM(G4:G15) -> 8839.0098 | H17: =SUM(H4:H15) -> 754.26434 | I17: =SUM(I4:I15) -> 593.2741 | J17: =SUM(J4:J15) -> 1200 | K17: =SUM(K4:K15) -> 274.06646 | L17: =SUM(L4:L15) -> 3136.5576 | M17: =SUM(M4:M15) -> 274.06646 | ... P17: =SUM(P4:P15) -> 9407.4169 | R17: =SUM(R4:R15) -> 0.66088874 | S17: =IF(AND(AJ17>0,AJ16<0),"Payback","") | T17: 1 | U17: 2 | V17: Fevereiro | W17: ='Análise Técnica'!$C$3 -> 750 | X17: =X5*(1-$C$26) -> 950.13435 | Y17: =IF(X17-W17<0,W17-X17,0) -> 0 | Z17: =IF(X17-W17>0,X17-W17,0) -> 200.13435 | AA17: =$C$7 -> 100 | AB17: =IF(Y17-$C$7>0,Y17-$C$7,0) -> 0 | AC17: =IF(AC16-(Y17-$C$7)>0,IF(Y17>0,IF(Y17<$C$7,AC16,AC16-(Y17-$C$7)),Z17+AC16),0) -> 671.46681 | AD17: =IF(AB17-AC16<0,0,AB17-AC16) -> 0 | AE17: =($C$10*(1+$C$30)^T17) -> 1012.5 | AF17: =IF(Z17>0,((AA17*$C$8)*((1+$C$30)^T17)),((AA17+AD17)*$C$8)*(1+$C$30)^T17) -> 135 | AG17: =AE17-AF17 -> 877.5 | AH17: =$C$28/12*($C$4*((1+$C$29)^T17))+IF($C$31=T17,$C$33/12,0) -> 0 | AI17: =AG17-AH17 -> 877.5 | AJ17: =AJ16+AI17 -> -2729.4942 | AK17: =1-(AF17/AE17) -> 0.86666667 | AL17: =AL16+AE17 -> 13275 | AM17: =AG17/$C$4 -> 0.061646026 | AO17: 14 | AP17: =($C$4*(1+($C$36-$C$39))^AO17)-AE17 -> 13797.147 | AQ17: =AJ17 -> -2729.4942
B18: TIR | C18: =IRR(M22:M46) -> 2.4280909 | S18: =IF(AND(AJ18>0,AJ17<0),"Payback","") | T18: 1 | U18: 3 | V18: Março | W18: ='Análise Técnica'!$C$3 -> 750 | X18: =X6*(1-$C$26) -> 797.33255 | Y18: =IF(X18-W18<0,W18-X18,0) -> 0 | Z18: =IF(X18-W18>0,X18-W18,0) -> 47.332548 | AA18: =$C$7 -> 100 | AB18: =IF(Y18-$C$7>0,Y18-$C$7,0) -> 0 | AC18: =IF(AC17-(Y18-$C$7)>0,IF(Y18>0,IF(Y18<$C$7,AC17,AC17-(Y18-$C$7)),Z18+AC17),0) -> 718.79935 | AD18: =IF(AB18-AC17<0,0,AB18-AC17) -> 0 | AE18: =($C$10*(1+$C$30)^T18) -> 1012.5 | AF18: =IF(Z18>0,((AA18*$C$8)*((1+$C$30)^T18)),((AA18+AD18)*$C$8)*(1+$C$30)^T18) -> 135 | AG18: =AE18-AF18 -> 877.5 | AH18: =$C$28/12*($C$4*((1+$C$29)^T18))+IF($C$31=T18,$C$33/12,0) -> 0 | AI18: =AG18-AH18 -> 877.5 | AJ18: =AJ17+AI18 -> -1851.9942 | AK18: =1-(AF18/AE18) -> 0.86666667 | AL18: =AL17+AE18 -> 14287.5 | AM18: =AG18/$C$4 -> 0.061646026 | AO18: 15 | AP18: =($C$4*(1+($C$36-$C$39))^AO18)-AE18 -> 13839.107 | AQ18: =AJ18 -> -1851.9942
B19: Lucro Final do Projeto após 25 anos | C19: =N46 -> 666757.49 | S19: =IF(AND(AJ19>0,AJ18<0),"Payback","") | T19: 1 | U19: 4 | V19: Abril | W19: ='Análise Técnica'!$C$3 -> 750 | X19: =X7*(1-$C$26) -> 707.04929 | Y19: =IF(X19-W19<0,W19-X19,0) -> 42.95071 | Z19: =IF(X19-W19>0,X19-W19,0) -> 0 | AA19: =$C$7 -> 100 | AB19: =IF(Y19-$C$7>0,Y19-$C$7,0) -> 0 | AC19: =IF(AC18-(Y19-$C$7)>0,IF(Y19>0,IF(Y19<$C$7,AC18,AC18-(Y19-$C$7)),Z19+AC18),0) -> 718.79935 | AD19: =IF(AB19-AC18<0,0,AB19-AC18) -> 0 | AE19: =($C$10*(1+$C$30)^T19) -> 1012.5 | AF19: =IF(Z19>0,((AA19*$C$8)*((1+$C$30)^T19)),((AA19+AD19)*$C$8)*(1+$C$30)^T19) -> 135 | AG19: =AE19-AF19 -> 877.5 | AH19: =$C$28/12*($C$4*((1+$C$29)^T19))+IF($C$31=T19,$C$33/12,0) -> 0 | AI19: =AG19-AH19 -> 877.5 | AJ19: =AJ18+AI19 -> -974.49424 | AK19: =1-(AF19/AE19) -> 0.86666667 | AL19: =AL18+AE19 -> 15300 | AM19: =AG19/$C$4 -> 0.061646026 | AO19: 16 | AP19: =($C$4*(1+($C$36-$C$39))^AO19)-AE19 -> 13881.187 | AQ19: =AJ19 -> -974.49424
B20: ROI | C20: =(N46-C4)/C4 -> 45.840968 | E20: Demonstrativo Energético e Financeiro dos 25 anos do projeto: | S20: =IF(AND(AJ20>0,AJ19<0),"Payback","") | T20: 1 | U20: 5 | V20: Maio | W20: ='Análise Técnica'!$C$3 -> 750 | X20: =X8*(1-$C$26) -> 582.27762 | Y20: =IF(X20-W20<0,W20-X20,0) -> 167.72238 | Z20: =IF(X20-W20>0,X20-W20,0) -> 0 | AA20: =$C$7 -> 100 | AB20: =IF(Y20-$C$7>0,Y20-$C$7,0) -> 67.72238 | AC20: =IF(AC19-(Y20-$C$7)>0,IF(Y20>0,IF(Y20<$C$7,AC19,AC19-(Y20-$C$7)),Z20+AC19),0) -> 651.07697 | AD20: =IF(AB20-AC19<0,0,AB20-AC19) -> 0 | AE20: =($C$10*(1+$C$30)^T20) -> 1012.5 | AF20: =IF(Z20>0,((AA20*$C$8)*((1+$C$30)^T20)),((AA20+AD20)*$C$8)*(1+$C$30)^T20) -> 135 | AG20: =AE20-AF20 -> 877.5 | AH20: =$C$28/12*($C$4*((1+$C$29)^T20))+IF($C$31=T20,$C$33/12,0) -> 0 | AI20: =AG20-AH20 -> 877.5 | AJ20: =AJ19+AI20 -> -96.994245 | AK20: =1-(AF20/AE20) -> 0.86666667 | AL20: =AL19+AE20 -> 16312.5 | AM20: =AG20/$C$4 -> 0.061646026 | AO20: 17 | AP20: =($C$4*(1+($C$36-$C$39))^AO20)-AE20 -> 13923.386 | AQ20: =AJ20 -> -96.994245
B21: Geração Diária Média de Energia (kWh/dia) | C21: =C23/365 -> 22.222961 | E21: Ano | F21: Consumo | G21: Geração | H21: Sem Energia Solar | I21: Com Energia Solar | J21: Economia | K21: Economia % | L21: Custos | M21: Subtotal | N21: Fluxo Final | O21: Acumulado Sem ES | P21: Retorno Invest. | S21: =IF(AND(AJ21>0,AJ20<0),"Payback","") -> Payback | T21: 1 | U21: 6 | V21: Junho | W21: ='Análise Técnica'!$C$3 -> 750 | X21: =X9*(1-$C$26) -> 538.48515 | Y21: =IF(X21-W21<0,W21-X21,0) -> 211.51485 | Z21: =IF(X21-W21>0,X21-W21,0) -> 0 | AA21: =$C$7 -> 100 | AB21: =IF(Y21-$C$7>0,Y21-$C$7,0) -> 111.51485 | AC21: =IF(AC20-(Y21-$C$7)>0,IF(Y21>0,IF(Y21<$C$7,AC20,AC20-(Y21-$C$7)),Z21+AC20),0) -> 539.56213 | AD21: =IF(AB21-AC20<0,0,AB21-AC20) -> 0 | AE21: =($C$10*(1+$C$30)^T21) -> 1012.5 | AF21: =IF(Z21>0,((AA21*$C$8)*((1+$C$30)^T21)),((AA21+AD21)*$C$8)*(1+$C$30)^T21) -> 135 | AG21: =AE21-AF21 -> 877.5 | AH21: =$C$28/12*($C$4*((1+$C$29)^T21))+IF($C$31=T21,$C$33/12,0) -> 0 | AI21: =AG21-AH21 -> 877.5 | AJ21: =AJ20+AI21 -> 780.50576 | AK21: =1-(AF21/AE21) -> 0.86666667 | AL21: =AL20+AE21 -> 17325 | AM21: =AG21/$C$4 -> 0.061646026 | AO21: 18 | AP21: =($C$4*(1+($C$36-$C$39))^AO21)-AE21 -> 13965.704 | AQ21: =AJ21 -> 780.50576
B22: Geração Mensal Média de Energia (kWh/mês) | C22: =C23/12 -> 675.94839 | E22: 0 | F22: =SUM(W4:W15) -> 9000 | G22: =SUM(X4:X15) -> 8839.0098 | H22: =SUM(AE4:AE15) -> 11250 | I22: =SUM(AF4:AF15) -> 1500 | J22: =SUM(AG4:AG15) -> 9750 | K22: =J22/H22 -> 0.86666667 | L22: =SUM(AH4:AH15) -> 14234.494 | M22: =SUM(AI4:AI15) -> -4484.4942 | N22: =M22 -> -4484.4942 | O22: =-H22 -> -11250 | P22: =J22/$C$4 -> 0.68495584 | S22: =IF(AND(AJ22>0,AJ21<0),"Payback","") | T22: 1 | U22: 7 | V22: Julho | W22: ='Análise Técnica'!$C$3 -> 750 | X22: =X10*(1-$C$26) -> 538.41143 | Y22: =IF(X22-W22<0,W22-X22,0) -> 211.58857 | Z22: =IF(X22-W22>0,X22-W22,0) -> 0 | AA22: =$C$7 -> 100 | AB22: =IF(Y22-$C$7>0,Y22-$C$7,0) -> 111.58857 | AC22: =IF(AC21-(Y22-$C$7)>0,IF(Y22>0,IF(Y22<$C$7,AC21,AC21-(Y22-$C$7)),Z22+AC21),0) -> 427.97356 | AD22: =IF(AB22-AC21<0,0,AB22-AC21) -> 0 | AE22: =($C$10*(1+$C$30)^T22) -> 1012.5 | AF22: =IF(Z22>0,((AA22*$C$8)*((1+$C$30)^T22)),((AA22+AD22)*$C$8)*(1+$C$30)^T22) -> 135 | AG22: =AE22-AF22 -> 877.5 | AH22: =$C$28/12*($C$4*((1+$C$29)^T22))+IF($C$31=T22,$C$33/12,0) -> 0 | AI22: =AG22-AH22 -> 877.5 | AJ22: =AJ21+AI22 -> 1658.0058 | AK22: =1-(AF22/AE22) -> 0.86666667 | AL22: =AL21+AE22 -> 18337.5 | AM22: =AG22/$C$4 -> 0.061646026 | AO22: 19 | AP22: =($C$4*(1+($C$36-$C$39))^AO22)-AE22 -> 14008.142 | AQ22: =AJ22 -> 1658.0058
B23: Geração Anual Média de Energia (kWh/ano) | C23: =AVERAGE(G22:G46) -> 8111.3806 | D23: =IF(AND(N23>0,N22<0),"Payback","") -> Payback | E23: 1 | F23: =SUM(W16:W27) -> 9000 | G23: =SUM(X16:X27) -> 8750.6197 | H23: =SUM(AE16:AE27) -> 12150 | I23: =SUM(AF16:AF27) -> 1620 | J23: =SUM(AG16:AG27) -> 10530 | K23: =J23/H23 -> 0.86666667 | L23: =SUM(AH16:AH27) -> 0 | M23: =SUM(AI16:AI27) -> 10530 | N23: =M22+M23 -> 6045.5058 | O23: =O22-H23 -> -23400 | P23: =J23/$C$4 -> 0.73975231 | S23: =IF(AND(AJ23>0,AJ22<0),"Payback","") | T23: 1 | U23: 8 | V23: Agosto | W23: ='Análise Técnica'!$C$3 -> 750 | X23: =X11*(1-$C$26) -> 665.79295 | Y23: =IF(X23-W23<0,W23-X23,0) -> 84.207048 | Z23: =IF(X23-W23>0,X23-W23,0) -> 0 | AA23: =$C$7 -> 100 | AB23: =IF(Y23-$C$7>0,Y23-$C$7,0) -> 0 | AC23: =IF(AC22-(Y23-$C$7)>0,IF(Y23>0,IF(Y23<$C$7,AC22,AC22-(Y23-$C$7)),Z23+AC22),0) -> 427.97356 | AD23: =IF(AB23-AC22<0,0,AB23-AC22) -> 0 | AE23: =($C$10*(1+$C$30)^T23) -> 1012.5 | AF23: =IF(Z23>0,((AA23*$C$8)*((1+$C$30)^T23)),((AA23+AD23)*$C$8)*(1+$C$30)^T23) -> 135 | AG23: =AE23-AF23 -> 877.5 | AH23: =$C$28/12*($C$4*((1+$C$29)^T23))+IF($C$31=T23,$C$33/12,0) -> 0 | AI23: =AG23-AH23 -> 877.5 | AJ23: =AJ22+AI23 -> 2535.5058 | AK23: =1-(AF23/AE23) -> 0.86666667 | AL23: =AL22+AE23 -> 19350 | AM23: =AG23/$C$4 -> 0.061646026 | AO23: 20 | AP23: =($C$4*(1+($C$36-$C$39))^AO23)-AE23 -> 14050.701 | AQ23: =AJ23 -> 2535.5058
B24: Custo do Kwh Solar (Valor Presente) | C24: =((I48+L48)/F48)/((1+$C$30)^25) -> 0.10103423 | D24: =IF(AND(N24>0,N23<0),"Payback","") | E24: 2 | F24: =SUM(W28:W39) -> 9000 | G24: =SUM(X28:X39) -> 8689.3653 | H24: =SUM(AE28:AE39) -> 13122 | I24: =SUM(AF28:AF39) -> 1749.6 | J24: =SUM(AG28:AG39) -> 11372.4 | K24: =J24/H24 -> 0.86666667 | L24: =SUM(AH28:AH39) -> 0 | M24: =SUM(AI28:AI39) -> 11372.4 | N24: =M24+N23 -> 17417.906 | O24: =O23-H24 -> -36522 | P24: =J24/$C$4 -> 0.79893249 | S24: =IF(AND(AJ24>0,AJ23<0),"Payback","") | T24: 1 | U24: 9 | V24: Setembro | W24: ='Análise Técnica'!$C$3 -> 750 | X24: =X12*(1-$C$26) -> 676.26186 | Y24: =IF(X24-W24<0,W24-X24,0) -> 73.738142 | Z24: =IF(X24-W24>0,X24-W24,0) -> 0 | AA24: =$C$7 -> 100 | AB24: =IF(Y24-$C$7>0,Y24-$C$7,0) -> 0 | AC24: =IF(AC23-(Y24-$C$7)>0,IF(Y24>0,IF(Y24<$C$7,AC23,AC23-(Y24-$C$7)),Z24+AC23),0) -> 427.97356 | AD24: =IF(AB24-AC23<0,0,AB24-AC23) -> 0 | AE24: =($C$10*(1+$C$30)^T24) -> 1012.5 | AF24: =IF(Z24>0,((AA24*$C$8)*((1+$C$30)^T24)),((AA24+AD24)*$C$8)*(1+$C$30)^T24) -> 135 | AG24: =AE24-AF24 -> 877.5 | AH24: =$C$28/12*($C$4*((1+$C$29)^T24))+IF($C$31=T24,$C$33/12,0) -> 0 | AI24: =AG24-AH24 -> 877.5 | AJ24: =AJ23+AI24 -> 3413.0058 | AK24: =1-(AF24/AE24) -> 0.86666667 | AL24: =AL23+AE24 -> 20362.5 | AM24: =AG24/$C$4 -> 0.061646026 | AO24: 21 | AP24: =($C$4*(1+($C$36-$C$39))^AO24)-AE24 -> 14093.38 | AQ24: =AJ24 -> 3413.0058
B25: Premissas e Taxas | D25: =IF(AND(N25>0,N24<0),"Payback","") | E25: 3 | F25: =SUM(W40:W51) -> 9000 | G25: =SUM(X40:X51) -> 8628.5398 | H25: =SUM(AE40:AE51) -> 14171.76 | I25: =SUM(AF40:AF51) -> 1889.568 | J25: =SUM(AG40:AG51) -> 12282.192 | K25: =J25/H25 -> 0.86666667 | L25: =SUM(AH40:AH51) -> 0 | M25: =SUM(AI40:AI51) -> 12282.192 | N25: =M25+N24 -> 29700.098 | O25: =O24-H25 -> -50693.76 | P25: =J25/$C$4 -> 0.86284709 | S25: =IF(AND(AJ25>0,AJ24<0),"Payback","") | T25: 1 | U25: 10 | V25: Outubro | W25: ='Análise Técnica'!$C$3 -> 750 | X25: =X13*(1-$C$26) -> 756.5333 | Y25: =IF(X25-W25<0,W25-X25,0) -> 0 | Z25: =IF(X25-W25>0,X25-W25,0) -> 6.5333034 | AA25: =$C$7 -> 100 | AB25: =IF(Y25-$C$7>0,Y25-$C$7,0) -> 0 | AC25: =IF(AC24-(Y25-$C$7)>0,IF(Y25>0,IF(Y25<$C$7,AC24,AC24-(Y25-$C$7)),Z25+AC24),0) -> 434.50686 | AD25: =IF(AB25-AC24<0,0,AB25-AC24) -> 0 | AE25: =($C$10*(1+$C$30)^T25) -> 1012.5 | AF25: =IF(Z25>0,((AA25*$C$8)*((1+$C$30)^T25)),((AA25+AD25)*$C$8)*(1+$C$30)^T25) -> 135 | AG25: =AE25-AF25 -> 877.5 | AH25: =$C$28/12*($C$4*((1+$C$29)^T25))+IF($C$31=T25,$C$33/12,0) -> 0 | AI25: =AG25-AH25 -> 877.5 | AJ25: =AJ24+AI25 -> 4290.5058 | AK25: =1-(AF25/AE25) -> 0.86666667 | AL25: =AL24+AE25 -> 21375 | AM25: =AG25/$C$4 -> 0.061646026 | AO25: 22 | AP25: =($C$4*(1+($C$36-$C$39))^AO25)-AE25 -> 14136.18 | AQ25: =AJ25 -> 4290.5058
B26: Degradação do Painéis Ano 1 | C26: 0.01 | D26: =IF(AND(N26>0,N25<0),"Payback","") | E26: 4 | F26: =SUM(W52:W63) -> 9000 | G26: =SUM(X52:X63) -> 8568.14 | H26: =SUM(AE52:AE63) -> 15305.501 | I26: =SUM(AF52:AF63) -> 2040.7334 | J26: =SUM(AG52:AG63) -> 13264.767 | K26: =J26/H26 -> 0.86666667 | L26: =SUM(AH52:AH63) -> 0 | M26: =SUM(AI52:AI63) -> 13264.767 | N26: =M26+N25 -> 42964.865 | O26: =O25-H26 -> -65999.261 | P26: =J26/$C$4 -> 0.93187486 | S26: =IF(AND(AJ26>0,AJ25<0),"Payback","") | T26: 1 | U26: 11 | V26: Novembro | W26: ='Análise Técnica'!$C$3 -> 750 | X26: =X14*(1-$C$26) -> 761.98893 | Y26: =IF(X26-W26<0,W26-X26,0) -> 0 | Z26: =IF(X26-W26>0,X26-W26,0) -> 11.988931 | AA26: =$C$7 -> 100 | AB26: =IF(Y26-$C$7>0,Y26-$C$7,0) -> 0 | AC26: =IF(AC25-(Y26-$C$7)>0,IF(Y26>0,IF(Y26<$C$7,AC25,AC25-(Y26-$C$7)),Z26+AC25),0) -> 446.49579 | AD26: =IF(AB26-AC25<0,0,AB26-AC25) -> 0 | AE26: =($C$10*(1+$C$30)^T26) -> 1012.5 | AF26: =IF(Z26>0,((AA26*$C$8)*((1+$C$30)^T26)),((AA26+AD26)*$C$8)*(1+$C$30)^T26) -> 135 | AG26: =AE26-AF26 -> 877.5 | AH26: =$C$28/12*($C$4*((1+$C$29)^T26))+IF($C$31=T26,$C$33/12,0) -> 0 | AI26: =AG26-AH26 -> 877.5 | AJ26: =AJ25+AI26 -> 5168.0058 | AK26: =1-(AF26/AE26) -> 0.86666667 | AL26: =AL25+AE26 -> 22387.5 | AM26: =AG26/$C$4 -> 0.061646026 | AO26: 23 | AP26: =($C$4*(1+($C$36-$C$39))^AO26)-AE26 -> 14179.101 | AQ26: =AJ26 -> 5168.0058
B27: Degradação outros anos | C27: 0.007 | D27: =IF(AND(N27>0,N26<0),"Payback","") | E27: 5 | F27: =SUM(W64:W75) -> 9000 | G27: =SUM(X64:X75) -> 8508.163 | H27: =SUM(AE64:AE75) -> 16529.941 | I27: =SUM(AF64:AF75) -> 2203.9921 | J27: =SUM(AG64:AG75) -> 14325.949 | K27: =J27/H27 -> 0.86666667 | L27: =SUM(AH64:AH75) -> 0 | M27: =SUM(AI64:AI75) -> 14325.949 | N27: =M27+N26 -> 57290.814 | O27: =O26-H27 -> -82529.202 | P27: =J27/$C$4 -> 1.0064249 | S27: =IF(AND(AJ27>0,AJ26<0),"Payback","") | T27: 1 | U27: 12 | V27: Dezembro | W27: ='Análise Técnica'!$C$3 -> 750 | X27: =X15*(1-$C$26) -> 874.2274 | Y27: =IF(X27-W27<0,W27-X27,0) -> 0 | Z27: =IF(X27-W27>0,X27-W27,0) -> 124.2274 | AA27: =$C$7 -> 100 | AB27: =IF(Y27-$C$7>0,Y27-$C$7,0) -> 0 | AC27: =IF(AC26-(Y27-$C$7)>0,IF(Y27>0,IF(Y27<$C$7,AC26,AC26-(Y27-$C$7)),Z27+AC26),0) -> 570.72319 | AD27: =IF(AB27-AC26<0,0,AB27-AC26) -> 0 | AE27: =($C$10*(1+$C$30)^T27) -> 1012.5 | AF27: =IF(Z27>0,((AA27*$C$8)*((1+$C$30)^T27)),((AA27+AD27)*$C$8)*(1+$C$30)^T27) -> 135 | AG27: =AE27-AF27 -> 877.5 | AH27: =$C$28/12*($C$4*((1+$C$29)^T27))+IF($C$31=T27,$C$33/12,0) -> 0 | AI27: =AG27-AH27 -> 877.5 | AJ27: =AJ26+AI27 -> 6045.5058 | AK27: =1-(AF27/AE27) -> 0.86666667 | AL27: =AL26+AE27 -> 23400 | AM27: =AG27/$C$4 -> 0.061646026 | AO27: 24 | AP27: =($C$4*(1+($C$36-$C$39))^AO27)-AE27 -> 14222.144 | AQ27: =AJ27 -> 6045.5058
B28: Custo de Manutenção / Ano | C28: 0 | D28: =IF(AND(N28>0,N27<0),"Payback","") | E28: 6 | F28: =SUM(W76:W87) -> 9000 | G28: =SUM(X76:X87) -> 8448.6059 | H28: =SUM(AE76:AE87) -> 17852.336 | I28: =SUM(AF76:AF87) -> 2380.3115 | J28: =SUM(AG76:AG87) -> 15472.025 | K28: =J28/H28 -> 0.86666667 | L28: =SUM(AH76:AH87) -> 0 | M28: =SUM(AI76:AI87) -> 15472.025 | N28: =M28+N27 -> 72762.839 | O28: =O27-H28 -> -100381.54 | P28: =J28/$C$4 -> 1.0869388 | S28: =IF(AND(AJ28>0,AJ27<0),"Payback","") | T28: 2 | U28: 1 | V28: Janeiro | W28: ='Análise Técnica'!$C$3 -> 750 | X28: =X16*((1-$C$27)) -> 895.80995 | Y28: =IF(X28-W28<0,W28-X28,0) -> 0 | Z28: =IF(X28-W28>0,X28-W28,0) -> 145.80995 | AA28: =$C$7 -> 100 | AB28: =IF(Y28-$C$7>0,Y28-$C$7,0) -> 0 | AC28: =IF(AC27-(Y28-$C$7)>0,IF(Y28>0,IF(Y28<$C$7,AC27,AC27-(Y28-$C$7)),Z28+AC27),0) -> 716.53315 | AD28: =IF(AB28-AC27<0,0,AB28-AC27) -> 0 | AE28: =($C$10*(1+$C$30)^T28) -> 1093.5 | AF28: =IF(Z28>0,((AA28*$C$8)*((1+$C$30)^T28)),((AA28+AD28)*$C$8)*(1+$C$30)^T28) -> 145.8 | AG28: =AE28-AF28 -> 947.7 | AH28: =$C$28/12*($C$4*((1+$C$29)^T28))+IF($C$31=T28,$C$33/12,0) -> 0 | AI28: =AG28-AH28 -> 947.7 | AJ28: =AJ27+AI28 -> 6993.2058 | AK28: =1-(AF28/AE28) -> 0.86666667 | AL28: =AL27+AE28 -> 24493.5 | AM28: =AG28/$C$4 -> 0.066577708 | AO28: 25 | AP28: =($C$4*(1+($C$36-$C$39))^AO28)-AE28 -> 14184.309 | AQ28: =AJ28 -> 6993.2058
B29: Inflação Projetada (%a.a.) | C29: 0.05 | D29: =IF(AND(N29>0,N28<0),"Payback","") | E29: 7 | F29: =SUM(W88:W99) -> 9000 | G29: =SUM(X88:X99) -> 8389.4656 | H29: =SUM(AE88:AE99) -> 19280.523 | I29: =SUM(AF88:AF99) -> 2570.7364 | J29: =SUM(AG88:AG99) -> 16709.787 | K29: =J29/H29 -> 0.86666667 | L29: =SUM(AH88:AH99) -> 0 | M29: =SUM(AI88:AI99) -> 16709.787 | N29: =M29+N28 -> 89472.625 | O29: =O28-H29 -> -119662.06 | P29: =J29/$C$4 -> 1.1738939 | S29: =IF(AND(AJ29>0,AJ28<0),"Payback","") | T29: 2 | U29: 2 | V29: Fevereiro | W29: ='Análise Técnica'!$C$3 -> 750 | X29: =X17*((1-$C$27)) -> 943.48341 | Y29: =IF(X29-W29<0,W29-X29,0) -> 0 | Z29: =IF(X29-W29>0,X29-W29,0) -> 193.48341 | AA29: =$C$7 -> 100 | AB29: =IF(Y29-$C$7>0,Y29-$C$7,0) -> 0 | AC29: =IF(AC28-(Y29-$C$7)>0,IF(Y29>0,IF(Y29<$C$7,AC28,AC28-(Y29-$C$7)),Z29+AC28),0) -> 910.01655 | AD29: =IF(AB29-AC28<0,0,AB29-AC28) -> 0 | AE29: =($C$10*(1+$C$30)^T29) -> 1093.5 | AF29: =IF(Z29>0,((AA29*$C$8)*((1+$C$30)^T29)),((AA29+AD29)*$C$8)*(1+$C$30)^T29) -> 145.8 | AG29: =AE29-AF29 -> 947.7 | AH29: =$C$28/12*($C$4*((1+$C$29)^T29))+IF($C$31=T29,$C$33/12,0) -> 0 | AI29: =AG29-AH29 -> 947.7 | AJ29: =AJ28+AI29 -> 7940.9058 | AK29: =1-(AF29/AE29) -> 0.86666667 | AL29: =AL28+AE29 -> 25587 | AM29: =AG29/$C$4 -> 0.066577708 | AO29: 26 | AP29: =($C$4*(1+($C$36-$C$39))^AO29)-AE29 -> 14227.596 | AQ29: =AJ29 -> 7940.9058
B30: Inflação Energética Projetada (%a.a.) | C30: 0.08 | D30: =IF(AND(N30>0,N29<0),"Payback","") | E30: 8 | F30: =SUM(W100:W111) -> 9000 | G30: =SUM(X100:X111) -> 8330.7394 | H30: =SUM(AE100:AE111) -> 20822.965 | I30: =SUM(AF100:AF111) -> 2776.3953 | J30: =SUM(AG100:AG111) -> 18046.57 | K30: =J30/H30 -> 0.86666667 | L30: =SUM(AH100:AH111) -> 0 | M30: =SUM(AI100:AI111) -> 18046.57 | N30: =M30+N29 -> 107519.19 | O30: =O29-H30 -> -140485.03 | P30: =J30/$C$4 -> 1.2678055 | S30: =IF(AND(AJ30>0,AJ29<0),"Payback","") | T30: 2 | U30: 3 | V30: Março | W30: ='Análise Técnica'!$C$3 -> 750 | X30: =X18*((1-$C$27)) -> 791.75122 | Y30: =IF(X30-W30<0,W30-X30,0) -> 0 | Z30: =IF(X30-W30>0,X30-W30,0) -> 41.75122 | AA30: =$C$7 -> 100 | AB30: =IF(Y30-$C$7>0,Y30-$C$7,0) -> 0 | AC30: =IF(AC29-(Y30-$C$7)>0,IF(Y30>0,IF(Y30<$C$7,AC29,AC29-(Y30-$C$7)),Z30+AC29),0) -> 951.76777 | AD30: =IF(AB30-AC29<0,0,AB30-AC29) -> 0 | AE30: =($C$10*(1+$C$30)^T30) -> 1093.5 | AF30: =IF(Z30>0,((AA30*$C$8)*((1+$C$30)^T30)),((AA30+AD30)*$C$8)*(1+$C$30)^T30) -> 145.8 | AG30: =AE30-AF30 -> 947.7 | AH30: =$C$28/12*($C$4*((1+$C$29)^T30))+IF($C$31=T30,$C$33/12,0) -> 0 | AI30: =AG30-AH30 -> 947.7 | AJ30: =AJ29+AI30 -> 8888.6058 | AK30: =1-(AF30/AE30) -> 0.86666667 | AL30: =AL29+AE30 -> 26680.5 | AM30: =AG30/$C$4 -> 0.066577708 | AO30: 27 | AP30: =($C$4*(1+($C$36-$C$39))^AO30)-AE30 -> 14271.006 | AQ30: =AJ30 -> 8888.6058
B31: Ano de troca do Inversor | C31: 15 | D31: =IF(AND(N31>0,N30<0),"Payback","") | E31: 9 | F31: =SUM(W112:W123) -> 9000 | G31: =SUM(X112:X123) -> 8272.4242 | H31: =SUM(AE112:AE123) -> 22488.802 | I31: =SUM(AF112:AF123) -> 2998.5069 | J31: =SUM(AG112:AG123) -> 19490.295 | K31: =J31/H31 -> 0.86666667 | L31: =SUM(AH112:AH123) -> 0 | M31: =SUM(AI112:AI123) -> 19490.295 | N31: =M31+N30 -> 127009.49 | O31: =O30-H31 -> -162973.83 | P31: =J31/$C$4 -> 1.3692299 | S31: =IF(AND(AJ31>0,AJ30<0),"Payback","") | T31: 2 | U31: 4 | V31: Abril | W31: ='Análise Técnica'!$C$3 -> 750 | X31: =X19*((1-$C$27)) -> 702.09994 | Y31: =IF(X31-W31<0,W31-X31,0) -> 47.900055 | Z31: =IF(X31-W31>0,X31-W31,0) -> 0 | AA31: =$C$7 -> 100 | AB31: =IF(Y31-$C$7>0,Y31-$C$7,0) -> 0 | AC31: =IF(AC30-(Y31-$C$7)>0,IF(Y31>0,IF(Y31<$C$7,AC30,AC30-(Y31-$C$7)),Z31+AC30),0) -> 951.76777 | AD31: =IF(AB31-AC30<0,0,AB31-AC30) -> 0 | AE31: =($C$10*(1+$C$30)^T31) -> 1093.5 | AF31: =IF(Z31>0,((AA31*$C$8)*((1+$C$30)^T31)),((AA31+AD31)*$C$8)*(1+$C$30)^T31) -> 145.8 | AG31: =AE31-AF31 -> 947.7 | AH31: =$C$28/12*($C$4*((1+$C$29)^T31))+IF($C$31=T31,$C$33/12,0) -> 0 | AI31: =AG31-AH31 -> 947.7 | AJ31: =AJ30+AI31 -> 9836.3058 | AK31: =1-(AF31/AE31) -> 0.86666667 | AL31: =AL30+AE31 -> 27774 | AM31: =AG31/$C$4 -> 0.066577708 | AO31: 28 | AP31: =($C$4*(1+($C$36-$C$39))^AO31)-AE31 -> 14314.538 | AQ31: =AJ31 -> 9836.3058
B32: Estimativa Custo % do Inversor no Sistema | C32: 0.15 | D32: =IF(AND(N32>0,N31<0),"Payback","") | E32: 10 | F32: =SUM(W124:W135) -> 9000 | G32: =SUM(X124:X135) -> 8214.5172 | H32: =SUM(AE124:AE135) -> 24287.906 | I32: =SUM(AF124:AF135) -> 3238.3875 | J32: =SUM(AG124:AG135) -> 21049.519 | K32: =J32/H32 -> 0.86666667 | L32: =SUM(AH124:AH135) -> 0 | M32: =SUM(AI124:AI135) -> 21049.519 | N32: =M32+N31 -> 148059.01 | O32: =O31-H32 -> -187261.73 | P32: =J32/$C$4 -> 1.4787683 | S32: =IF(AND(AJ32>0,AJ31<0),"Payback","") | T32: 2 | U32: 5 | V32: Maio | W32: ='Análise Técnica'!$C$3 -> 750 | X32: =X20*((1-$C$27)) -> 578.20168 | Y32: =IF(X32-W32<0,W32-X32,0) -> 171.79832 | Z32: =IF(X32-W32>0,X32-W32,0) -> 0 | AA32: =$C$7 -> 100 | AB32: =IF(Y32-$C$7>0,Y32-$C$7,0) -> 71.798323 | AC32: =IF(AC31-(Y32-$C$7)>0,IF(Y32>0,IF(Y32<$C$7,AC31,AC31-(Y32-$C$7)),Z32+AC31),0) -> 879.96945 | AD32: =IF(AB32-AC31<0,0,AB32-AC31) -> 0 | AE32: =($C$10*(1+$C$30)^T32) -> 1093.5 | AF32: =IF(Z32>0,((AA32*$C$8)*((1+$C$30)^T32)),((AA32+AD32)*$C$8)*(1+$C$30)^T32) -> 145.8 | AG32: =AE32-AF32 -> 947.7 | AH32: =$C$28/12*($C$4*((1+$C$29)^T32))+IF($C$31=T32,$C$33/12,0) -> 0 | AI32: =AG32-AH32 -> 947.7 | AJ32: =AJ31+AI32 -> 10784.006 | AK32: =1-(AF32/AE32) -> 0.86666667 | AL32: =AL31+AE32 -> 28867.5 | AM32: =AG32/$C$4 -> 0.066577708 | AO32: 29 | AP32: =($C$4*(1+($C$36-$C$39))^AO32)-AE32 -> 14358.195 | AQ32: =AJ32 -> 10784.006
B33: Estim. Custo % do Inversor no Sist. ano troca | C33: =C32*C4 -> 2135.1741 | D33: =IF(AND(N33>0,N32<0),"Payback","") | E33: 11 | F33: =SUM(W136:W147) -> 9000 | G33: =SUM(X136:X147) -> 8157.0156 | H33: =SUM(AE136:AE147) -> 26230.939 | I33: =SUM(AF136:AF147) -> 3497.4585 | J33: =SUM(AG136:AG147) -> 22733.48 | K33: =J33/H33 -> 0.86666667 | L33: =SUM(AH136:AH147) -> 0 | M33: =SUM(AI136:AI147) -> 22733.48 | N33: =M33+N32 -> 170792.49 | O33: =O32-H33 -> -213492.67 | P33: =J33/$C$4 -> 1.5970698 | S33: =IF(AND(AJ33>0,AJ32<0),"Payback","") | T33: 2 | U33: 6 | V33: Junho | W33: ='Análise Técnica'!$C$3 -> 750 | X33: =X21*((1-$C$27)) -> 534.71576 | Y33: =IF(X33-W33<0,W33-X33,0) -> 215.28424 | Z33: =IF(X33-W33>0,X33-W33,0) -> 0 | AA33: =$C$7 -> 100 | AB33: =IF(Y33-$C$7>0,Y33-$C$7,0) -> 115.28424 | AC33: =IF(AC32-(Y33-$C$7)>0,IF(Y33>0,IF(Y33<$C$7,AC32,AC32-(Y33-$C$7)),Z33+AC32),0) -> 764.6852 | AD33: =IF(AB33-AC32<0,0,AB33-AC32) -> 0 | AE33: =($C$10*(1+$C$30)^T33) -> 1093.5 | AF33: =IF(Z33>0,((AA33*$C$8)*((1+$C$30)^T33)),((AA33+AD33)*$C$8)*(1+$C$30)^T33) -> 145.8 | AG33: =AE33-AF33 -> 947.7 | AH33: =$C$28/12*($C$4*((1+$C$29)^T33))+IF($C$31=T33,$C$33/12,0) -> 0 | AI33: =AG33-AH33 -> 947.7 | AJ33: =AJ32+AI33 -> 11731.706 | AK33: =1-(AF33/AE33) -> 0.86666667 | AL33: =AL32+AE33 -> 29961 | AM33: =AG33/$C$4 -> 0.066577708 | AO33: 30 | AP33: =($C$4*(1+($C$36-$C$39))^AO33)-AE33 -> 14401.974 | AQ33: =AJ33 -> 11731.706
B34: Custo de Capital (Wacc) | C34: 0.1 | D34: =IF(AND(N34>0,N33<0),"Payback","") | E34: 12 | F34: =SUM(W148:W159) -> 9000 | G34: =SUM(X148:X159) -> 8099.9165 | H34: =SUM(AE148:AE159) -> 28329.414 | I34: =SUM(AF148:AF159) -> 3777.2552 | J34: =SUM(AG148:AG159) -> 24552.159 | K34: =J34/H34 -> 0.86666667 | L34: =SUM(AH148:AH159) -> 0 | M34: =SUM(AI148:AI159) -> 24552.159 | N34: =M34+N33 -> 195344.65 | O34: =O33-H34 -> -241822.09 | P34: =J34/$C$4 -> 1.7248353 | S34: =IF(AND(AJ34>0,AJ33<0),"Payback","") | T34: 2 | U34: 7 | V34: Julho | W34: ='Análise Técnica'!$C$3 -> 750 | X34: =X22*((1-$C$27)) -> 534.64255 | Y34: =IF(X34-W34<0,W34-X34,0) -> 215.35745 | Z34: =IF(X34-W34>0,X34-W34,0) -> 0 | AA34: =$C$7 -> 100 | AB34: =IF(Y34-$C$7>0,Y34-$C$7,0) -> 115.35745 | AC34: =IF(AC33-(Y34-$C$7)>0,IF(Y34>0,IF(Y34<$C$7,AC33,AC33-(Y34-$C$7)),Z34+AC33),0) -> 649.32775 | AD34: =IF(AB34-AC33<0,0,AB34-AC33) -> 0 | AE34: =($C$10*(1+$C$30)^T34) -> 1093.5 | AF34: =IF(Z34>0,((AA34*$C$8)*((1+$C$30)^T34)),((AA34+AD34)*$C$8)*(1+$C$30)^T34) -> 145.8 | AG34: =AE34-AF34 -> 947.7 | AH34: =$C$28/12*($C$4*((1+$C$29)^T34))+IF($C$31=T34,$C$33/12,0) -> 0 | AI34: =AG34-AH34 -> 947.7 | AJ34: =AJ33+AI34 -> 12679.406 | AK34: =1-(AF34/AE34) -> 0.86666667 | AL34: =AL33+AE34 -> 31054.5 | AM34: =AG34/$C$4 -> 0.066577708 | AO34: 31 | AP34: =($C$4*(1+($C$36-$C$39))^AO34)-AE34 -> 14445.878 | AQ34: =AJ34 -> 12679.406
B35: Indices Monetários | D35: =IF(AND(N35>0,N34<0),"Payback","") | E35: 13 | F35: =SUM(W160:W171) -> 9000 | G35: =SUM(X160:X171) -> 8043.2171 | H35: =SUM(AE160:AE171) -> 30595.767 | I35: =SUM(AF160:AF171) -> 4079.4356 | J35: =SUM(AG160:AG171) -> 26516.331 | K35: =J35/H35 -> 0.86666667 | L35: =SUM(AH160:AH171) -> 0 | M35: =SUM(AI160:AI171) -> 26516.331 | N35: =M35+N34 -> 221860.98 | O35: =O34-H35 -> -272417.85 | P35: =J35/$C$4 -> 1.8628222 | S35: =IF(AND(AJ35>0,AJ34<0),"Payback","") | T35: 2 | U35: 8 | V35: Agosto | W35: ='Análise Técnica'!$C$3 -> 750 | X35: =X23*((1-$C$27)) -> 661.1324 | Y35: =IF(X35-W35<0,W35-X35,0) -> 88.867599 | Z35: =IF(X35-W35>0,X35-W35,0) -> 0 | AA35: =$C$7 -> 100 | AB35: =IF(Y35-$C$7>0,Y35-$C$7,0) -> 0 | AC35: =IF(AC34-(Y35-$C$7)>0,IF(Y35>0,IF(Y35<$C$7,AC34,AC34-(Y35-$C$7)),Z35+AC34),0) -> 649.32775 | AD35: =IF(AB35-AC34<0,0,AB35-AC34) -> 0 | AE35: =($C$10*(1+$C$30)^T35) -> 1093.5 | AF35: =IF(Z35>0,((AA35*$C$8)*((1+$C$30)^T35)),((AA35+AD35)*$C$8)*(1+$C$30)^T35) -> 145.8 | AG35: =AE35-AF35 -> 947.7 | AH35: =$C$28/12*($C$4*((1+$C$29)^T35))+IF($C$31=T35,$C$33/12,0) -> 0 | AI35: =AG35-AH35 -> 947.7 | AJ35: =AJ34+AI35 -> 13627.106 | AK35: =1-(AF35/AE35) -> 0.86666667 | AL35: =AL34+AE35 -> 32148 | AM35: =AG35/$C$4 -> 0.066577708 | AO35: 32 | AP35: =($C$4*(1+($C$36-$C$39))^AO35)-AE35 -> 14489.906 | AQ35: =AJ35 -> 13627.106
B36: Poupança (a.m.) | C36: 0.007 | D36: =IF(AND(N36>0,N35<0),"Payback","") | E36: 14 | F36: =SUM(W172:W183) -> 9000 | G36: =SUM(X172:X183) -> 7986.9146 | H36: =SUM(AE172:AE183) -> 33043.428 | I36: =SUM(AF172:AF183) -> 4405.7904 | J36: =SUM(AG172:AG183) -> 28637.638 | K36: =J36/H36 -> 0.86666667 | L36: =SUM(AH172:AH183) -> 0 | M36: =SUM(AI172:AI183) -> 28637.638 | N36: =M36+N35 -> 250498.62 | O36: =O35-H36 -> -305461.28 | P36: =J36/$C$4 -> 2.0118479 | S36: =IF(AND(AJ36>0,AJ35<0),"Payback","") | T36: 2 | U36: 9 | V36: Setembro | W36: ='Análise Técnica'!$C$3 -> 750 | X36: =X24*((1-$C$27)) -> 671.52803 | Y36: =IF(X36-W36<0,W36-X36,0) -> 78.471975 | Z36: =IF(X36-W36>0,X36-W36,0) -> 0 | AA36: =$C$7 -> 100 | AB36: =IF(Y36-$C$7>0,Y36-$C$7,0) -> 0 | AC36: =IF(AC35-(Y36-$C$7)>0,IF(Y36>0,IF(Y36<$C$7,AC35,AC35-(Y36-$C$7)),Z36+AC35),0) -> 649.32775 | AD36: =IF(AB36-AC35<0,0,AB36-AC35) -> 0 | AE36: =($C$10*(1+$C$30)^T36) -> 1093.5 | AF36: =IF(Z36>0,((AA36*$C$8)*((1+$C$30)^T36)),((AA36+AD36)*$C$8)*(1+$C$30)^T36) -> 145.8 | AG36: =AE36-AF36 -> 947.7 | AH36: =$C$28/12*($C$4*((1+$C$29)^T36))+IF($C$31=T36,$C$33/12,0) -> 0 | AI36: =AG36-AH36 -> 947.7 | AJ36: =AJ35+AI36 -> 14574.806 | AK36: =1-(AF36/AE36) -> 0.86666667 | AL36: =AL35+AE36 -> 33241.5 | AM36: =AG36/$C$4 -> 0.066577708 | AO36: 33 | AP36: =($C$4*(1+($C$36-$C$39))^AO36)-AE36 -> 14534.059 | AQ36: =AJ36 -> 14574.806
B37: Poupança (a.a.) | C37: =12*C36 -> 0.084 | D37: =IF(AND(N37>0,N36<0),"Payback","") | E37: 15 | F37: =SUM(W184:W195) -> 9000 | G37: =SUM(X184:X195) -> 7931.0062 | H37: =SUM(AE184:AE195) -> 35686.903 | I37: =SUM(AF184:AF195) -> 5839.3016 | J37: =SUM(AG184:AG195) -> 29847.601 | K37: =J37/H37 -> 0.8363741 | L37: =SUM(AH184:AH195) -> 2135.1741 | M37: =SUM(AI184:AI195) -> 27712.427 | N37: =M37+N36 -> 278211.04 | O37: =O36-H37 -> -341148.18 | P37: =J37/$C$4 -> 2.0968501 | S37: =IF(AND(AJ37>0,AJ36<0),"Payback","") | T37: 2 | U37: 10 | V37: Outubro | W37: ='Análise Técnica'!$C$3 -> 750 | X37: =X25*((1-$C$27)) -> 751.23757 | Y37: =IF(X37-W37<0,W37-X37,0) -> 0 | Z37: =IF(X37-W37>0,X37-W37,0) -> 1.2375703 | AA37: =$C$7 -> 100 | AB37: =IF(Y37-$C$7>0,Y37-$C$7,0) -> 0 | AC37: =IF(AC36-(Y37-$C$7)>0,IF(Y37>0,IF(Y37<$C$7,AC36,AC36-(Y37-$C$7)),Z37+AC36),0) -> 650.56532 | AD37: =IF(AB37-AC36<0,0,AB37-AC36) -> 0 | AE37: =($C$10*(1+$C$30)^T37) -> 1093.5 | AF37: =IF(Z37>0,((AA37*$C$8)*((1+$C$30)^T37)),((AA37+AD37)*$C$8)*(1+$C$30)^T37) -> 145.8 | AG37: =AE37-AF37 -> 947.7 | AH37: =$C$28/12*($C$4*((1+$C$29)^T37))+IF($C$31=T37,$C$33/12,0) -> 0 | AI37: =AG37-AH37 -> 947.7 | AJ37: =AJ36+AI37 -> 15522.506 | AK37: =1-(AF37/AE37) -> 0.86666667 | AL37: =AL36+AE37 -> 34335 | AM37: =AG37/$C$4 -> 0.066577708 | AO37: 34 | AP37: =($C$4*(1+($C$36-$C$39))^AO37)-AE37 -> 14578.337 | AQ37: =AJ37 -> 15522.506
B38: Inflação (a.a) | C38: =C29 -> 0.05 | D38: =IF(AND(N38>0,N37<0),"Payback","") | E38: 16 | F38: =SUM(W196:W207) -> 9000 | G38: =SUM(X196:X207) -> 7875.4891 | H38: =SUM(AE196:AE207) -> 38541.855 | I38: =SUM(AF196:AF207) -> 6651.5346 | J38: =SUM(AG196:AG207) -> 31890.32 | K38: =J38/H38 -> 0.82742049 | L38: =SUM(AH196:AH207) -> 0 | M38: =SUM(AI196:AI207) -> 31890.32 | N38: =M38+N37 -> 310101.36 | O38: =O37-H38 -> -379690.04 | P38: =J38/$C$4 -> 2.240355 | S38: =IF(AND(AJ38>0,AJ37<0),"Payback","") | T38: 2 | U38: 11 | V38: Novembro | W38: ='Análise Técnica'!$C$3 -> 750 | X38: =X26*((1-$C$27)) -> 756.65501 | Y38: =IF(X38-W38<0,W38-X38,0) -> 0 | Z38: =IF(X38-W38>0,X38-W38,0) -> 6.6550081 | AA38: =$C$7 -> 100 | AB38: =IF(Y38-$C$7>0,Y38-$C$7,0) -> 0 | AC38: =IF(AC37-(Y38-$C$7)>0,IF(Y38>0,IF(Y38<$C$7,AC37,AC37-(Y38-$C$7)),Z38+AC37),0) -> 657.22033 | AD38: =IF(AB38-AC37<0,0,AB38-AC37) -> 0 | AE38: =($C$10*(1+$C$30)^T38) -> 1093.5 | AF38: =IF(Z38>0,((AA38*$C$8)*((1+$C$30)^T38)),((AA38+AD38)*$C$8)*(1+$C$30)^T38) -> 145.8 | AG38: =AE38-AF38 -> 947.7 | AH38: =$C$28/12*($C$4*((1+$C$29)^T38))+IF($C$31=T38,$C$33/12,0) -> 0 | AI38: =AG38-AH38 -> 947.7 | AJ38: =AJ37+AI38 -> 16470.206 | AK38: =1-(AF38/AE38) -> 0.86666667 | AL38: =AL37+AE38 -> 35428.5 | AM38: =AG38/$C$4 -> 0.066577708 | AO38: 35 | AP38: =($C$4*(1+($C$36-$C$39))^AO38)-AE38 -> 14622.741 | AQ38: =AJ38 -> 16470.206
B39: Inflação (a.m.) | C39: =C38/12 -> 0.0041666667 | D39: =IF(AND(N39>0,N38<0),"Payback","") | E39: 17 | F39: =SUM(W208:W219) -> 9000 | G39: =SUM(X208:X219) -> 7820.3607 | H39: =SUM(AE208:AE219) -> 41625.203 | I39: =SUM(AF208:AF219) -> 7371.3292 | J39: =SUM(AG208:AG219) -> 34253.874 | K39: =J39/H39 -> 0.82291188 | L39: =SUM(AH208:AH219) -> 0 | M39: =SUM(AI208:AI219) -> 34253.874 | N39: =M39+N38 -> 344355.24 | O39: =O38-H39 -> -421315.24 | P39: =J39/$C$4 -> 2.4063991 | S39: =IF(AND(AJ39>0,AJ38<0),"Payback","") | T39: 2 | U39: 12 | V39: Dezembro | W39: ='Análise Técnica'!$C$3 -> 750 | X39: =X27*((1-$C$27)) -> 868.10781 | Y39: =IF(X39-W39<0,W39-X39,0) -> 0 | Z39: =IF(X39-W39>0,X39-W39,0) -> 118.10781 | AA39: =$C$7 -> 100 | AB39: =IF(Y39-$C$7>0,Y39-$C$7,0) -> 0 | AC39: =IF(AC38-(Y39-$C$7)>0,IF(Y39>0,IF(Y39<$C$7,AC38,AC38-(Y39-$C$7)),Z39+AC38),0) -> 775.32814 | AD39: =IF(AB39-AC38<0,0,AB39-AC38) -> 0 | AE39: =($C$10*(1+$C$30)^T39) -> 1093.5 | AF39: =IF(Z39>0,((AA39*$C$8)*((1+$C$30)^T39)),((AA39+AD39)*$C$8)*(1+$C$30)^T39) -> 145.8 | AG39: =AE39-AF39 -> 947.7 | AH39: =$C$28/12*($C$4*((1+$C$29)^T39))+IF($C$31=T39,$C$33/12,0) -> 0 | AI39: =AG39-AH39 -> 947.7 | AJ39: =AJ38+AI39 -> 17417.906 | AK39: =1-(AF39/AE39) -> 0.86666667 | AL39: =AL38+AE39 -> 36522 | AM39: =AG39/$C$4 -> 0.066577708 | AO39: 36 | AP39: =($C$4*(1+($C$36-$C$39))^AO39)-AE39 -> 14667.27 | AQ39: =AJ39 -> 17417.906
D40: =IF(AND(N40>0,N39<0),"Payback","") | E40: 18 | F40: =SUM(W220:W231) -> 9000 | G40: =SUM(X220:X231) -> 7765.6182 | H40: =SUM(AE220:AE231) -> 44955.219 | I40: =SUM(AF220:AF231) -> 8162.3023 | J40: =SUM(AG220:AG231) -> 36792.917 | K40: =J40/H40 -> 0.81843483 | L40: =SUM(AH220:AH231) -> 0 | M40: =SUM(AI220:AI231) -> 36792.917 | N40: =M40+N39 -> 381148.15 | O40: =O39-H40 -> -466270.46 | P40: =J40/$C$4 -> 2.5847716 | S40: =IF(AND(AJ40>0,AJ39<0),"Payback","") | T40: 3 | U40: 1 | V40: Janeiro | W40: ='Análise Técnica'!$C$3 -> 750 | X40: =X28*((1-$C$27)) -> 889.53928 | Y40: =IF(X40-W40<0,W40-X40,0) -> 0 | Z40: =IF(X40-W40>0,X40-W40,0) -> 139.53928 | AA40: =$C$7 -> 100 | AB40: =IF(Y40-$C$7>0,Y40-$C$7,0) -> 0 | AC40: =IF(AC39-(Y40-$C$7)>0,IF(Y40>0,IF(Y40<$C$7,AC39,AC39-(Y40-$C$7)),Z40+AC39),0) -> 914.86742 | AD40: =IF(AB40-AC39<0,0,AB40-AC39) -> 0 | AE40: =($C$10*(1+$C$30)^T40) -> 1180.98 | AF40: =IF(Z40>0,((AA40*$C$8)*((1+$C$30)^T40)),((AA40+AD40)*$C$8)*(1+$C$30)^T40) -> 157.464 | AG40: =AE40-AF40 -> 1023.516 | AH40: =$C$28/12*($C$4*((1+$C$29)^T40))+IF($C$31=T40,$C$33/12,0) -> 0 | AI40: =AG40-AH40 -> 1023.516 | AJ40: =AJ39+AI40 -> 18441.422 | AK40: =1-(AF40/AE40) -> 0.86666667 | AL40: =AL39+AE40 -> 37702.98 | AM40: =AG40/$C$4 -> 0.071903925 | AO40: 37 | AP40: =($C$4*(1+($C$36-$C$39))^AO40)-AE40 -> 14624.446 | AQ40: =AJ40 -> 18441.422
D41: =IF(AND(N41>0,N40<0),"Payback","") | E41: 19 | F41: =SUM(W232:W243) -> 9000 | G41: =SUM(X232:X243) -> 7711.2588 | H41: =SUM(AE232:AE243) -> 48551.637 | I41: =SUM(AF232:AF243) -> 9031.133 | J41: =SUM(AG232:AG243) -> 39520.504 | K41: =J41/H41 -> 0.81398911 | L41: =SUM(AH232:AH243) -> 0 | M41: =SUM(AI232:AI243) -> 39520.504 | N41: =M41+N40 -> 420668.66 | O41: =O40-H41 -> -514822.1 | P41: =J41/$C$4 -> 2.7763898 | S41: =IF(AND(AJ41>0,AJ40<0),"Payback","") | T41: 3 | U41: 2 | V41: Fevereiro | W41: ='Análise Técnica'!$C$3 -> 750 | X41: =X29*((1-$C$27)) -> 936.87902 | Y41: =IF(X41-W41<0,W41-X41,0) -> 0 | Z41: =IF(X41-W41>0,X41-W41,0) -> 186.87902 | AA41: =$C$7 -> 100 | AB41: =IF(Y41-$C$7>0,Y41-$C$7,0) -> 0 | AC41: =IF(AC40-(Y41-$C$7)>0,IF(Y41>0,IF(Y41<$C$7,AC40,AC40-(Y41-$C$7)),Z41+AC40),0) -> 1101.7464 | AD41: =IF(AB41-AC40<0,0,AB41-AC40) -> 0 | AE41: =($C$10*(1+$C$30)^T41) -> 1180.98 | AF41: =IF(Z41>0,((AA41*$C$8)*((1+$C$30)^T41)),((AA41+AD41)*$C$8)*(1+$C$30)^T41) -> 157.464 | AG41: =AE41-AF41 -> 1023.516 | AH41: =$C$28/12*($C$4*((1+$C$29)^T41))+IF($C$31=T41,$C$33/12,0) -> 0 | AI41: =AG41-AH41 -> 1023.516 | AJ41: =AJ40+AI41 -> 19464.938 | AK41: =1-(AF41/AE41) -> 0.86666667 | AL41: =AL40+AE41 -> 38883.96 | AM41: =AG41/$C$4 -> 0.071903925 | AO41: 38 | AP41: =($C$4*(1+($C$36-$C$39))^AO41)-AE41 -> 14669.228 | AQ41: =AJ41 -> 19464.938
...

Sheet Correção K
A1: Cód. | B1: Latitude | C1: Inclnação | D1: Jan | E1: Fev | F1: Mar | G1: Abr | H1: Mai | I1: Jun | J1: Jul | K1: Ago | L1: Set | M1: Out | N1: Nov | O1: Dez | P1: Média
